INFO 2022-05-30 14:57:13,006 - Watching for file changes with StatReloader
WARNING 2022-05-30 14:57:49,706 - Not Found: /
INFO 2022-05-30 14:58:05,239 - XMl response None
WARNING 2022-05-30 14:58:05,251 - Not Found: /add-users
DEBUG 2022-05-30 14:59:27,330 - Using proactor: IocpProactor
INFO 2022-05-30 15:00:34,869 - Watching for file changes with StatReloader
INFO 2022-05-30 15:02:17,049 - C:\DevOpsTools_Automation\Automation%20Platform\DVT_api\models.py changed, reloading.
DEBUG 2022-05-30 15:02:17,051 - Using proactor: IocpProactor
INFO 2022-05-30 15:02:18,898 - Watching for file changes with StatReloader
INFO 2022-05-30 15:02:50,451 - XMl response None
INFO 2022-05-30 15:02:53,698 - XMl response None
WARNING 2022-05-30 15:02:53,820 - Not Found: /add-users
INFO 2022-05-30 15:04:28,175 - C:\DevOpsTools_Automation\Automation%20Platform\DVT_api\models.py changed, reloading.
DEBUG 2022-05-30 15:04:28,175 - Using proactor: IocpProactor
INFO 2022-05-30 15:04:29,794 - Watching for file changes with StatReloader
INFO 2022-05-30 15:05:00,930 - XMl response None
WARNING 2022-05-30 15:05:00,943 - Not Found: /add-users
INFO 2022-05-30 15:10:56,399 - C:\DevOpsTools_Automation\Automation%20Platform\DVT_api\views.py changed, reloading.
DEBUG 2022-05-30 15:10:56,400 - Using proactor: IocpProactor
INFO 2022-05-30 15:10:58,141 - Watching for file changes with StatReloader
INFO 2022-05-30 15:11:30,541 - XMl response None
WARNING 2022-05-30 15:11:30,554 - Not Found: /add-users
INFO 2022-05-30 15:17:43,690 - C:\DevOpsTools_Automation\Automation%20Platform\DVT_api\views.py changed, reloading.
DEBUG 2022-05-30 15:17:43,692 - Using proactor: IocpProactor
INFO 2022-05-30 15:17:46,221 - Watching for file changes with StatReloader
INFO 2022-05-30 15:17:55,698 - C:\DevOpsTools_Automation\Automation%20Platform\DVT_api\models.py changed, reloading.
DEBUG 2022-05-30 15:17:55,699 - Using proactor: IocpProactor
INFO 2022-05-30 15:17:57,515 - Watching for file changes with StatReloader
INFO 2022-05-30 15:18:12,282 - XMl response None
WARNING 2022-05-30 15:18:12,388 - Not Found: /add-users
INFO 2022-05-30 15:26:23,026 - C:\DevOpsTools_Automation\Automation%20Platform\DVT_api\views.py changed, reloading.
DEBUG 2022-05-30 15:26:23,026 - Using proactor: IocpProactor
INFO 2022-05-30 15:26:25,088 - Watching for file changes with StatReloader
INFO 2022-05-30 15:27:20,600 - XMl response None
WARNING 2022-05-30 15:27:20,613 - Not Found: /add-users
INFO 2022-05-30 15:29:19,993 - C:\DevOpsTools_Automation\Automation%20Platform\DVT_api\models.py changed, reloading.
DEBUG 2022-05-30 15:29:19,994 - Using proactor: IocpProactor
INFO 2022-05-30 15:29:22,317 - Watching for file changes with StatReloader
INFO 2022-05-30 16:21:14,679 - Watching for file changes with StatReloader
INFO 2022-05-30 16:21:47,760 - C:\DevOpsTools_Automation\Automation%20Platform\DVT_api\views.py changed, reloading.
DEBUG 2022-05-30 16:21:47,761 - Using proactor: IocpProactor
INFO 2022-05-30 16:21:49,723 - Watching for file changes with StatReloader
INFO 2022-05-30 16:22:49,041 - XMl response None
WARNING 2022-05-30 16:22:49,139 - Not Found: /add-users
INFO 2022-05-30 16:24:39,070 - C:\DevOpsTools_Automation\Automation%20Platform\DVT_api\GUM_API.py changed, reloading.
DEBUG 2022-05-30 16:24:39,071 - Using proactor: IocpProactor
INFO 2022-05-30 16:24:40,879 - Watching for file changes with StatReloader
WARNING 2022-05-30 16:24:44,338 - Not Found: /add-users
INFO 2022-05-30 16:25:01,035 - XMl response None
WARNING 2022-05-30 16:25:01,044 - Not Found: /add-users
INFO 2022-05-30 16:33:35,802 - C:\DevOpsTools_Automation\Automation%20Platform\DVT_api\GUM_API.py changed, reloading.
DEBUG 2022-05-30 16:33:35,804 - Using proactor: IocpProactor
INFO 2022-05-30 16:33:38,691 - Watching for file changes with StatReloader
INFO 2022-05-30 16:34:19,887 - XMl response None
WARNING 2022-05-30 16:34:19,993 - Not Found: /add-users
WARNING 2022-05-30 16:36:42,984 - Not Found: /add-users
WARNING 2022-05-30 16:36:49,704 - Not Found: /
INFO 2022-05-30 16:38:36,866 - C:\DevOpsTools_Automation\Automation%20Platform\DVT_api\models.py changed, reloading.
DEBUG 2022-05-30 16:38:36,867 - Using proactor: IocpProactor
INFO 2022-05-30 16:38:39,421 - Watching for file changes with StatReloader
INFO 2022-05-30 16:38:54,125 - XMl response None
WARNING 2022-05-30 16:38:54,145 - Not Found: /add-users
INFO 2022-05-30 16:40:26,170 - C:\DevOpsTools_Automation\Automation%20Platform\DVT_api\views.py changed, reloading.
DEBUG 2022-05-30 16:40:26,172 - Using proactor: IocpProactor
INFO 2022-05-30 16:40:29,290 - Watching for file changes with StatReloader
INFO 2022-05-30 16:40:46,827 - XMl response None
WARNING 2022-05-30 16:40:46,846 - Not Found: /add-users
INFO 2022-05-30 16:41:37,081 - C:\DevOpsTools_Automation\Automation%20Platform\DVT_api\views.py changed, reloading.
DEBUG 2022-05-30 16:41:37,082 - Using proactor: IocpProactor
INFO 2022-05-30 16:41:39,575 - Watching for file changes with StatReloader
INFO 2022-05-30 16:42:16,911 - C:\DevOpsTools_Automation\Automation%20Platform\DVT_api\views.py changed, reloading.
DEBUG 2022-05-30 16:42:16,912 - Using proactor: IocpProactor
INFO 2022-05-30 16:42:19,645 - Watching for file changes with StatReloader
INFO 2022-05-30 16:42:24,649 - XMl response None
WARNING 2022-05-30 16:42:24,675 - Not Found: /add-users
INFO 2022-05-30 16:43:59,570 - C:\DevOpsTools_Automation\Automation%20Platform\DVT_api\models.py changed, reloading.
DEBUG 2022-05-30 16:43:59,571 - Using proactor: IocpProactor
INFO 2022-05-30 16:44:01,763 - Watching for file changes with StatReloader
INFO 2022-05-30 16:46:50,114 - C:\DevOpsTools_Automation\Automation%20Platform\DVT_api\views.py changed, reloading.
DEBUG 2022-05-30 16:46:50,116 - Using proactor: IocpProactor
INFO 2022-05-30 16:46:53,002 - Watching for file changes with StatReloader
WARNING 2022-05-30 16:46:53,909 - Not Found: /add-users
WARNING 2022-05-30 16:47:01,222 - Not Found: /add-users
INFO 2022-05-30 16:54:26,253 - C:\DevOpsTools_Automation\Automation%20Platform\DVT_api\GUM_API.py changed, reloading.
DEBUG 2022-05-30 16:54:26,254 - Using proactor: IocpProactor
INFO 2022-05-30 16:54:28,669 - Watching for file changes with StatReloader
INFO 2022-05-30 16:55:41,868 - C:\DevOpsTools_Automation\Automation%20Platform\DVT_api\views.py changed, reloading.
DEBUG 2022-05-30 16:55:41,869 - Using proactor: IocpProactor
INFO 2022-05-30 16:55:43,661 - Watching for file changes with StatReloader
INFO 2022-05-30 16:56:50,300 - C:\DevOpsTools_Automation\Automation%20Platform\DVT_api\views.py changed, reloading.
DEBUG 2022-05-30 16:56:50,301 - Using proactor: IocpProactor
INFO 2022-05-30 16:56:53,024 - Watching for file changes with StatReloader
WARNING 2022-05-30 16:57:11,345 - Not Found: /add-users
INFO 2022-05-30 17:02:48,560 - C:\DevOpsTools_Automation\Automation%20Platform\DVT_api\views.py changed, reloading.
DEBUG 2022-05-30 17:02:48,561 - Using proactor: IocpProactor
INFO 2022-05-30 17:02:51,305 - Watching for file changes with StatReloader
WARNING 2022-05-30 17:02:59,829 - Not Found: /add-users
INFO 2022-05-30 17:03:48,920 - C:\DevOpsTools_Automation\Automation%20Platform\DVT_api\views.py changed, reloading.
DEBUG 2022-05-30 17:03:48,921 - Using proactor: IocpProactor
INFO 2022-05-30 17:03:51,764 - Watching for file changes with StatReloader
WARNING 2022-05-30 17:04:03,040 - Not Found: /add-users
WARNING 2022-05-30 17:04:07,705 - Not Found: /add-users
INFO 2022-05-31 00:28:23,615 - C:\DevOpsTools_Automation\Automation%20Platform\DVT_api\models.py changed, reloading.
DEBUG 2022-05-31 00:28:23,641 - Using proactor: IocpProactor
INFO 2022-05-31 00:28:26,749 - Watching for file changes with StatReloader
INFO 2022-05-31 00:29:48,750 - C:\DevOpsTools_Automation\Automation%20Platform\DVT_api\views.py changed, reloading.
DEBUG 2022-05-31 00:29:48,751 - Using proactor: IocpProactor
INFO 2022-05-31 00:29:50,437 - Watching for file changes with StatReloader
WARNING 2022-05-31 00:30:07,355 - Not Found: /add-users
INFO 2022-05-31 19:49:52,284 - C:\DevOpsTools_Automation\Automation%20Platform\DVT_api\views.py changed, reloading.
DEBUG 2022-05-31 19:49:52,308 - Using proactor: IocpProactor
INFO 2022-05-31 19:49:54,849 - Watching for file changes with StatReloader
WARNING 2022-05-31 19:51:46,448 - Not Found: /add-users
WARNING 2022-05-31 19:51:56,931 - Not Found: /add-users
INFO 2022-05-31 19:56:29,390 - C:\DevOpsTools_Automation\Automation%20Platform\DVT_api\views.py changed, reloading.
DEBUG 2022-05-31 19:56:29,390 - Using proactor: IocpProactor
INFO 2022-05-31 19:56:33,345 - Watching for file changes with StatReloader
WARNING 2022-05-31 19:56:47,891 - Not Found: /add-users
INFO 2022-05-31 20:01:33,346 - C:\DevOpsTools_Automation\Automation%20Platform\DVT_api\views.py changed, reloading.
DEBUG 2022-05-31 20:01:33,347 - Using proactor: IocpProactor
INFO 2022-05-31 20:01:36,284 - Watching for file changes with StatReloader
WARNING 2022-05-31 20:02:36,673 - Not Found: /add-users
INFO 2022-05-31 20:10:48,645 - C:\DevOpsTools_Automation\Automation%20Platform\DVT_api\views.py changed, reloading.
DEBUG 2022-05-31 20:10:48,647 - Using proactor: IocpProactor
INFO 2022-05-31 20:10:51,211 - Watching for file changes with StatReloader
WARNING 2022-05-31 20:11:01,965 - Not Found: /
WARNING 2022-05-31 20:11:02,628 - Not Found: /
WARNING 2022-05-31 20:11:23,523 - Not Found: /add-users
WARNING 2022-05-31 20:11:43,430 - Not Found: /add-users
INFO 2022-05-31 20:18:16,330 - C:\DevOpsTools_Automation\Automation%20Platform\DVT_api\views.py changed, reloading.
DEBUG 2022-05-31 20:18:16,331 - Using proactor: IocpProactor
INFO 2022-05-31 20:18:19,638 - Watching for file changes with StatReloader
WARNING 2022-05-31 20:18:37,835 - Not Found: /add-users
WARNING 2022-05-31 20:18:48,740 - Not Found: /add-users
INFO 2022-05-31 20:26:03,222 - C:\DevOpsTools_Automation\Automation%20Platform\DVT_api\GUM_API.py changed, reloading.
DEBUG 2022-05-31 20:26:03,223 - Using proactor: IocpProactor
INFO 2022-05-31 20:26:05,671 - Watching for file changes with StatReloader
INFO 2022-05-31 20:28:27,734 - C:\DevOpsTools_Automation\Automation%20Platform\DVT_api\views.py changed, reloading.
DEBUG 2022-05-31 20:28:27,735 - Using proactor: IocpProactor
INFO 2022-05-31 20:28:29,369 - Watching for file changes with StatReloader
INFO 2022-05-31 20:30:05,365 - C:\DevOpsTools_Automation\Automation%20Platform\DVT_api\views.py changed, reloading.
DEBUG 2022-05-31 20:30:05,367 - Using proactor: IocpProactor
INFO 2022-05-31 20:30:07,171 - Watching for file changes with StatReloader
WARNING 2022-05-31 20:30:18,935 - Not Found: /add-users
WARNING 2022-06-01 12:58:08,288 - Not Found: /api-token-auth
WARNING 2022-06-01 12:59:04,601 - Not Found: /api-token-auth
DEBUG 2022-06-01 13:01:55,182 - Using proactor: IocpProactor
DEBUG 2022-06-01 13:01:55,377 - Using proactor: IocpProactor
DEBUG 2022-06-01 13:02:06,211 - Using proactor: IocpProactor
INFO 2022-06-01 13:03:17,329 - Watching for file changes with StatReloader
INFO 2022-06-01 13:07:11,920 - Validating user information by GUID
ERROR 2022-06-01 13:07:12,201 - Internal Server Error: /api/post_user
Traceback (most recent call last):
  File "C:\Users\candon001\AppData\Local\Programs\Python\Python39\lib\site-packages\django\core\handlers\exception.py", line 47, in inner
    response = get_response(request)
  File "C:\Users\candon001\AppData\Local\Programs\Python\Python39\lib\site-packages\django\core\handlers\base.py", line 181, in _get_response
    response = wrapped_callback(request, *callback_args, **callback_kwargs)
  File "C:\Users\candon001\AppData\Local\Programs\Python\Python39\lib\site-packages\django\views\decorators\csrf.py", line 54, in wrapped_view
    return view_func(*args, **kwargs)
  File "C:\Users\candon001\AppData\Local\Programs\Python\Python39\lib\site-packages\django\views\decorators\csrf.py", line 54, in wrapped_view
    return view_func(*args, **kwargs)
  File "C:\Users\candon001\AppData\Local\Programs\Python\Python39\lib\site-packages\django\views\generic\base.py", line 70, in view
    return self.dispatch(request, *args, **kwargs)
  File "C:\Users\candon001\AppData\Local\Programs\Python\Python39\lib\site-packages\rest_framework\views.py", line 509, in dispatch
    response = self.handle_exception(exc)
  File "C:\Users\candon001\AppData\Local\Programs\Python\Python39\lib\site-packages\rest_framework\views.py", line 469, in handle_exception
    self.raise_uncaught_exception(exc)
  File "C:\Users\candon001\AppData\Local\Programs\Python\Python39\lib\site-packages\rest_framework\views.py", line 480, in raise_uncaught_exception
    raise exc
  File "C:\Users\candon001\AppData\Local\Programs\Python\Python39\lib\site-packages\rest_framework\views.py", line 506, in dispatch
    response = handler(request, *args, **kwargs)
  File "C:\Users\candon001\AppData\Local\Programs\Python\Python39\lib\site-packages\rest_framework\decorators.py", line 50, in handler
    return func(*args, **kwargs)
  File "C:\DevOpsTools_Automation\Automation%20Platform\DVT_api\views.py", line 66, in post_user
    guid = serializer.validated_data['guid']
  File "C:\Users\candon001\AppData\Local\Programs\Python\Python39\lib\site-packages\rest_framework\serializers.py", line 271, in validated_data
    raise AssertionError(msg)
AssertionError: You must call `.is_valid()` before accessing `.validated_data`.
INFO 2022-06-01 13:11:57,261 - C:\DevOpsTools_Automation\Automation%20Platform\DVT_api\views.py changed, reloading.
DEBUG 2022-06-01 13:11:57,262 - Using proactor: IocpProactor
INFO 2022-06-01 13:11:58,990 - Watching for file changes with StatReloader
INFO 2022-06-01 13:12:17,075 - Validating user information by GUID
DEBUG 2022-06-01 13:12:17,092 - Starting new HTTPS connection (1): gumapiservice.pwcinternal.com:443
DEBUG 2022-06-01 13:12:20,288 - https://gumapiservice.pwcinternal.com:443 "POST /GumService.asmx?wsdl HTTP/1.1" 200 1035
ERROR 2022-06-01 13:12:20,332 - Internal Server Error: /api/post_user
Traceback (most recent call last):
  File "C:\Users\candon001\AppData\Local\Programs\Python\Python39\lib\site-packages\django\core\handlers\exception.py", line 47, in inner
    response = get_response(request)
  File "C:\Users\candon001\AppData\Local\Programs\Python\Python39\lib\site-packages\django\core\handlers\base.py", line 181, in _get_response
    response = wrapped_callback(request, *callback_args, **callback_kwargs)
  File "C:\Users\candon001\AppData\Local\Programs\Python\Python39\lib\site-packages\django\views\decorators\csrf.py", line 54, in wrapped_view
    return view_func(*args, **kwargs)
  File "C:\Users\candon001\AppData\Local\Programs\Python\Python39\lib\site-packages\django\views\decorators\csrf.py", line 54, in wrapped_view
    return view_func(*args, **kwargs)
  File "C:\Users\candon001\AppData\Local\Programs\Python\Python39\lib\site-packages\django\views\generic\base.py", line 70, in view
    return self.dispatch(request, *args, **kwargs)
  File "C:\Users\candon001\AppData\Local\Programs\Python\Python39\lib\site-packages\rest_framework\views.py", line 511, in dispatch
    self.response = self.finalize_response(request, response, *args, **kwargs)
  File "C:\Users\candon001\AppData\Local\Programs\Python\Python39\lib\site-packages\rest_framework\views.py", line 423, in finalize_response
    assert isinstance(response, HttpResponseBase), (
AssertionError: Expected a `Response`, `HttpResponse` or `HttpStreamingResponse` to be returned from the view, but received a `<class 'NoneType'>`
INFO 2022-06-01 13:13:42,378 - Validating user information by GUID
DEBUG 2022-06-01 13:13:42,380 - Starting new HTTPS connection (1): gumapiservice.pwcinternal.com:443
DEBUG 2022-06-01 13:13:48,576 - https://gumapiservice.pwcinternal.com:443 "POST /GumService.asmx?wsdl HTTP/1.1" 200 1035
ERROR 2022-06-01 13:13:48,605 - Internal Server Error: /api/post_user
Traceback (most recent call last):
  File "C:\Users\candon001\AppData\Local\Programs\Python\Python39\lib\site-packages\django\core\handlers\exception.py", line 47, in inner
    response = get_response(request)
  File "C:\Users\candon001\AppData\Local\Programs\Python\Python39\lib\site-packages\django\core\handlers\base.py", line 181, in _get_response
    response = wrapped_callback(request, *callback_args, **callback_kwargs)
  File "C:\Users\candon001\AppData\Local\Programs\Python\Python39\lib\site-packages\django\views\decorators\csrf.py", line 54, in wrapped_view
    return view_func(*args, **kwargs)
  File "C:\Users\candon001\AppData\Local\Programs\Python\Python39\lib\site-packages\django\views\decorators\csrf.py", line 54, in wrapped_view
    return view_func(*args, **kwargs)
  File "C:\Users\candon001\AppData\Local\Programs\Python\Python39\lib\site-packages\django\views\generic\base.py", line 70, in view
    return self.dispatch(request, *args, **kwargs)
  File "C:\Users\candon001\AppData\Local\Programs\Python\Python39\lib\site-packages\rest_framework\views.py", line 511, in dispatch
    self.response = self.finalize_response(request, response, *args, **kwargs)
  File "C:\Users\candon001\AppData\Local\Programs\Python\Python39\lib\site-packages\rest_framework\views.py", line 423, in finalize_response
    assert isinstance(response, HttpResponseBase), (
AssertionError: Expected a `Response`, `HttpResponse` or `HttpStreamingResponse` to be returned from the view, but received a `<class 'NoneType'>`
INFO 2022-06-01 13:17:51,609 - C:\DevOpsTools_Automation\Automation%20Platform\DVT_api\models.py changed, reloading.
DEBUG 2022-06-01 13:17:51,610 - Using proactor: IocpProactor
INFO 2022-06-01 13:17:54,274 - Watching for file changes with StatReloader
INFO 2022-06-01 13:18:12,892 - Validating user information by GUID
DEBUG 2022-06-01 13:18:12,899 - Starting new HTTPS connection (1): gumapiservice.pwcinternal.com:443
DEBUG 2022-06-01 13:18:16,242 - https://gumapiservice.pwcinternal.com:443 "POST /GumService.asmx?wsdl HTTP/1.1" 200 1035
ERROR 2022-06-01 13:18:16,449 - Internal Server Error: /api/post_user
Traceback (most recent call last):
  File "C:\Users\candon001\AppData\Local\Programs\Python\Python39\lib\site-packages\rest_framework\serializers.py", line 962, in create
    instance = ModelClass._default_manager.create(**validated_data)
  File "C:\Users\candon001\AppData\Local\Programs\Python\Python39\lib\site-packages\django\db\models\manager.py", line 85, in manager_method
    return getattr(self.get_queryset(), name)(*args, **kwargs)
  File "C:\Users\candon001\AppData\Local\Programs\Python\Python39\lib\site-packages\django\db\models\query.py", line 453, in create
    obj.save(force_insert=True, using=self.db)
  File "C:\DevOpsTools_Automation\Automation%20Platform\DVT_api\models.py", line 38, in save
    xmlToString = etree.tostring(response, pretty_print = True)
  File "src\lxml\etree.pyx", line 3445, in lxml.etree.tostring
TypeError: Type 'bytes' cannot be serialized.

During handling of the above exception, another exception occurred:

Traceback (most recent call last):
  File "C:\Users\candon001\AppData\Local\Programs\Python\Python39\lib\site-packages\django\core\handlers\exception.py", line 47, in inner
    response = get_response(request)
  File "C:\Users\candon001\AppData\Local\Programs\Python\Python39\lib\site-packages\django\core\handlers\base.py", line 181, in _get_response
    response = wrapped_callback(request, *callback_args, **callback_kwargs)
  File "C:\Users\candon001\AppData\Local\Programs\Python\Python39\lib\site-packages\django\views\decorators\csrf.py", line 54, in wrapped_view
    return view_func(*args, **kwargs)
  File "C:\Users\candon001\AppData\Local\Programs\Python\Python39\lib\site-packages\django\views\decorators\csrf.py", line 54, in wrapped_view
    return view_func(*args, **kwargs)
  File "C:\Users\candon001\AppData\Local\Programs\Python\Python39\lib\site-packages\django\views\generic\base.py", line 70, in view
    return self.dispatch(request, *args, **kwargs)
  File "C:\Users\candon001\AppData\Local\Programs\Python\Python39\lib\site-packages\rest_framework\views.py", line 509, in dispatch
    response = self.handle_exception(exc)
  File "C:\Users\candon001\AppData\Local\Programs\Python\Python39\lib\site-packages\rest_framework\views.py", line 469, in handle_exception
    self.raise_uncaught_exception(exc)
  File "C:\Users\candon001\AppData\Local\Programs\Python\Python39\lib\site-packages\rest_framework\views.py", line 480, in raise_uncaught_exception
    raise exc
  File "C:\Users\candon001\AppData\Local\Programs\Python\Python39\lib\site-packages\rest_framework\views.py", line 506, in dispatch
    response = handler(request, *args, **kwargs)
  File "C:\Users\candon001\AppData\Local\Programs\Python\Python39\lib\site-packages\rest_framework\decorators.py", line 50, in handler
    return func(*args, **kwargs)
  File "C:\DevOpsTools_Automation\Automation%20Platform\DVT_api\views.py", line 71, in post_user
    serializer.save()
  File "C:\Users\candon001\AppData\Local\Programs\Python\Python39\lib\site-packages\rest_framework\serializers.py", line 212, in save
    self.instance = self.create(validated_data)
  File "C:\Users\candon001\AppData\Local\Programs\Python\Python39\lib\site-packages\rest_framework\serializers.py", line 981, in create
    raise TypeError(msg)
TypeError: Got a `TypeError` when calling `EventApp.objects.create()`. This may be because you have a writable field on the serializer class that is not a valid argument to `EventApp.objects.create()`. You may need to make the field read-only, or override the UserSerializer.create() method to handle this correctly.
Original exception was:
 Traceback (most recent call last):
  File "C:\Users\candon001\AppData\Local\Programs\Python\Python39\lib\site-packages\rest_framework\serializers.py", line 962, in create
    instance = ModelClass._default_manager.create(**validated_data)
  File "C:\Users\candon001\AppData\Local\Programs\Python\Python39\lib\site-packages\django\db\models\manager.py", line 85, in manager_method
    return getattr(self.get_queryset(), name)(*args, **kwargs)
  File "C:\Users\candon001\AppData\Local\Programs\Python\Python39\lib\site-packages\django\db\models\query.py", line 453, in create
    obj.save(force_insert=True, using=self.db)
  File "C:\DevOpsTools_Automation\Automation%20Platform\DVT_api\models.py", line 38, in save
    xmlToString = etree.tostring(response, pretty_print = True)
  File "src\lxml\etree.pyx", line 3445, in lxml.etree.tostring
TypeError: Type 'bytes' cannot be serialized.

INFO 2022-06-01 13:26:23,455 - C:\DevOpsTools_Automation\Automation%20Platform\DVT_api\models.py changed, reloading.
DEBUG 2022-06-01 13:26:23,457 - Using proactor: IocpProactor
INFO 2022-06-01 13:26:25,416 - Watching for file changes with StatReloader
INFO 2022-06-01 13:26:37,707 - Validating user information by GUID
DEBUG 2022-06-01 13:26:37,713 - Starting new HTTPS connection (1): gumapiservice.pwcinternal.com:443
DEBUG 2022-06-01 13:26:40,780 - https://gumapiservice.pwcinternal.com:443 "POST /GumService.asmx?wsdl HTTP/1.1" 200 1035
ERROR 2022-06-01 13:26:40,835 - Internal Server Error: /api/post_user
Traceback (most recent call last):
  File "C:\Users\candon001\AppData\Local\Programs\Python\Python39\lib\site-packages\django\core\handlers\exception.py", line 47, in inner
    response = get_response(request)
  File "C:\Users\candon001\AppData\Local\Programs\Python\Python39\lib\site-packages\django\core\handlers\base.py", line 181, in _get_response
    response = wrapped_callback(request, *callback_args, **callback_kwargs)
  File "C:\Users\candon001\AppData\Local\Programs\Python\Python39\lib\site-packages\django\views\decorators\csrf.py", line 54, in wrapped_view
    return view_func(*args, **kwargs)
  File "C:\Users\candon001\AppData\Local\Programs\Python\Python39\lib\site-packages\django\views\decorators\csrf.py", line 54, in wrapped_view
    return view_func(*args, **kwargs)
  File "C:\Users\candon001\AppData\Local\Programs\Python\Python39\lib\site-packages\django\views\generic\base.py", line 70, in view
    return self.dispatch(request, *args, **kwargs)
  File "C:\Users\candon001\AppData\Local\Programs\Python\Python39\lib\site-packages\rest_framework\views.py", line 511, in dispatch
    self.response = self.finalize_response(request, response, *args, **kwargs)
  File "C:\Users\candon001\AppData\Local\Programs\Python\Python39\lib\site-packages\rest_framework\views.py", line 423, in finalize_response
    assert isinstance(response, HttpResponseBase), (
AssertionError: Expected a `Response`, `HttpResponse` or `HttpStreamingResponse` to be returned from the view, but received a `<class 'NoneType'>`
INFO 2022-06-02 17:54:36,126 - C:\DevOpsTools_Automation\Automation%20Platform\DVT_api\models.py changed, reloading.
DEBUG 2022-06-02 17:54:36,165 - Using proactor: IocpProactor
INFO 2022-06-02 17:54:39,189 - Watching for file changes with StatReloader
DEBUG 2022-06-02 18:06:12,357 - Using proactor: IocpProactor
DEBUG 2022-06-02 18:06:12,530 - Using proactor: IocpProactor
DEBUG 2022-06-02 18:07:11,672 - Using proactor: IocpProactor
DEBUG 2022-06-02 18:07:39,910 - Using proactor: IocpProactor
DEBUG 2022-06-02 18:08:20,244 - Using proactor: IocpProactor
DEBUG 2022-06-02 18:09:41,020 - Using proactor: IocpProactor
DEBUG 2022-06-02 18:09:52,833 - Using proactor: IocpProactor
DEBUG 2022-06-02 18:15:42,251 - Using proactor: IocpProactor
DEBUG 2022-06-02 18:16:45,693 - Using proactor: IocpProactor
DEBUG 2022-06-02 18:18:17,639 - Using proactor: IocpProactor
INFO 2022-06-02 18:18:31,316 - Watching for file changes with StatReloader
DEBUG 2022-06-02 18:18:53,344 - Using proactor: IocpProactor
DEBUG 2022-06-02 18:18:53,463 - Using proactor: IocpProactor
DEBUG 2022-06-02 18:19:06,598 - Using proactor: IocpProactor
DEBUG 2022-06-02 18:19:28,645 - Using proactor: IocpProactor
DEBUG 2022-06-02 18:20:09,110 - Using proactor: IocpProactor
INFO 2022-06-02 18:23:09,006 - Watching for file changes with StatReloader
INFO 2022-06-02 18:23:51,790 - Validating user information by GUID
DEBUG 2022-06-02 18:23:51,799 - Starting new HTTPS connection (1): gumapiservice.pwcinternal.com:443
DEBUG 2022-06-02 18:23:54,322 - https://gumapiservice.pwcinternal.com:443 "POST /GumService.asmx?wsdl HTTP/1.1" 200 1032
ERROR 2022-06-02 18:23:54,524 - Internal Server Error: /api/post_user
Traceback (most recent call last):
  File "C:\Users\candon001\AppData\Local\Programs\Python\Python39\lib\site-packages\django\core\handlers\exception.py", line 47, in inner
    response = get_response(request)
  File "C:\Users\candon001\AppData\Local\Programs\Python\Python39\lib\site-packages\django\core\handlers\base.py", line 181, in _get_response
    response = wrapped_callback(request, *callback_args, **callback_kwargs)
  File "C:\Users\candon001\AppData\Local\Programs\Python\Python39\lib\site-packages\django\views\decorators\csrf.py", line 54, in wrapped_view
    return view_func(*args, **kwargs)
  File "C:\Users\candon001\AppData\Local\Programs\Python\Python39\lib\site-packages\django\views\decorators\csrf.py", line 54, in wrapped_view
    return view_func(*args, **kwargs)
  File "C:\Users\candon001\AppData\Local\Programs\Python\Python39\lib\site-packages\django\views\generic\base.py", line 70, in view
    return self.dispatch(request, *args, **kwargs)
  File "C:\Users\candon001\AppData\Local\Programs\Python\Python39\lib\site-packages\rest_framework\views.py", line 511, in dispatch
    self.response = self.finalize_response(request, response, *args, **kwargs)
  File "C:\Users\candon001\AppData\Local\Programs\Python\Python39\lib\site-packages\rest_framework\views.py", line 423, in finalize_response
    assert isinstance(response, HttpResponseBase), (
AssertionError: Expected a `Response`, `HttpResponse` or `HttpStreamingResponse` to be returned from the view, but received a `<class 'NoneType'>`
INFO 2022-06-02 18:24:53,003 - Validating user information by GUID
DEBUG 2022-06-02 18:24:53,005 - Starting new HTTPS connection (1): gumapiservice.pwcinternal.com:443
DEBUG 2022-06-02 18:24:55,258 - https://gumapiservice.pwcinternal.com:443 "POST /GumService.asmx?wsdl HTTP/1.1" 200 1032
ERROR 2022-06-02 18:24:55,300 - Internal Server Error: /api/post_user
Traceback (most recent call last):
  File "C:\Users\candon001\AppData\Local\Programs\Python\Python39\lib\site-packages\django\core\handlers\exception.py", line 47, in inner
    response = get_response(request)
  File "C:\Users\candon001\AppData\Local\Programs\Python\Python39\lib\site-packages\django\core\handlers\base.py", line 181, in _get_response
    response = wrapped_callback(request, *callback_args, **callback_kwargs)
  File "C:\Users\candon001\AppData\Local\Programs\Python\Python39\lib\site-packages\django\views\decorators\csrf.py", line 54, in wrapped_view
    return view_func(*args, **kwargs)
  File "C:\Users\candon001\AppData\Local\Programs\Python\Python39\lib\site-packages\django\views\decorators\csrf.py", line 54, in wrapped_view
    return view_func(*args, **kwargs)
  File "C:\Users\candon001\AppData\Local\Programs\Python\Python39\lib\site-packages\django\views\generic\base.py", line 70, in view
    return self.dispatch(request, *args, **kwargs)
  File "C:\Users\candon001\AppData\Local\Programs\Python\Python39\lib\site-packages\rest_framework\views.py", line 511, in dispatch
    self.response = self.finalize_response(request, response, *args, **kwargs)
  File "C:\Users\candon001\AppData\Local\Programs\Python\Python39\lib\site-packages\rest_framework\views.py", line 423, in finalize_response
    assert isinstance(response, HttpResponseBase), (
AssertionError: Expected a `Response`, `HttpResponse` or `HttpStreamingResponse` to be returned from the view, but received a `<class 'NoneType'>`
INFO 2022-06-02 18:25:17,843 - Validating user information by GUID
DEBUG 2022-06-02 18:25:17,845 - Starting new HTTPS connection (1): gumapiservice.pwcinternal.com:443
DEBUG 2022-06-02 18:25:19,935 - https://gumapiservice.pwcinternal.com:443 "POST /GumService.asmx?wsdl HTTP/1.1" 200 1035
ERROR 2022-06-02 18:25:19,984 - Internal Server Error: /api/post_user
Traceback (most recent call last):
  File "C:\Users\candon001\AppData\Local\Programs\Python\Python39\lib\site-packages\django\core\handlers\exception.py", line 47, in inner
    response = get_response(request)
  File "C:\Users\candon001\AppData\Local\Programs\Python\Python39\lib\site-packages\django\core\handlers\base.py", line 181, in _get_response
    response = wrapped_callback(request, *callback_args, **callback_kwargs)
  File "C:\Users\candon001\AppData\Local\Programs\Python\Python39\lib\site-packages\django\views\decorators\csrf.py", line 54, in wrapped_view
    return view_func(*args, **kwargs)
  File "C:\Users\candon001\AppData\Local\Programs\Python\Python39\lib\site-packages\django\views\decorators\csrf.py", line 54, in wrapped_view
    return view_func(*args, **kwargs)
  File "C:\Users\candon001\AppData\Local\Programs\Python\Python39\lib\site-packages\django\views\generic\base.py", line 70, in view
    return self.dispatch(request, *args, **kwargs)
  File "C:\Users\candon001\AppData\Local\Programs\Python\Python39\lib\site-packages\rest_framework\views.py", line 511, in dispatch
    self.response = self.finalize_response(request, response, *args, **kwargs)
  File "C:\Users\candon001\AppData\Local\Programs\Python\Python39\lib\site-packages\rest_framework\views.py", line 423, in finalize_response
    assert isinstance(response, HttpResponseBase), (
AssertionError: Expected a `Response`, `HttpResponse` or `HttpStreamingResponse` to be returned from the view, but received a `<class 'NoneType'>`
INFO 2022-06-02 18:27:56,206 - Validating user information by GUID
DEBUG 2022-06-02 18:27:56,209 - Starting new HTTPS connection (1): gumapiservice.pwcinternal.com:443
DEBUG 2022-06-02 18:27:58,364 - https://gumapiservice.pwcinternal.com:443 "POST /GumService.asmx?wsdl HTTP/1.1" 200 1032
ERROR 2022-06-02 18:27:58,531 - Internal Server Error: /api/post_user
Traceback (most recent call last):
  File "C:\Users\candon001\AppData\Local\Programs\Python\Python39\lib\site-packages\django\core\handlers\exception.py", line 47, in inner
    response = get_response(request)
  File "C:\Users\candon001\AppData\Local\Programs\Python\Python39\lib\site-packages\django\core\handlers\base.py", line 181, in _get_response
    response = wrapped_callback(request, *callback_args, **callback_kwargs)
  File "C:\Users\candon001\AppData\Local\Programs\Python\Python39\lib\site-packages\django\views\decorators\csrf.py", line 54, in wrapped_view
    return view_func(*args, **kwargs)
  File "C:\Users\candon001\AppData\Local\Programs\Python\Python39\lib\site-packages\django\views\decorators\csrf.py", line 54, in wrapped_view
    return view_func(*args, **kwargs)
  File "C:\Users\candon001\AppData\Local\Programs\Python\Python39\lib\site-packages\django\views\generic\base.py", line 70, in view
    return self.dispatch(request, *args, **kwargs)
  File "C:\Users\candon001\AppData\Local\Programs\Python\Python39\lib\site-packages\rest_framework\views.py", line 511, in dispatch
    self.response = self.finalize_response(request, response, *args, **kwargs)
  File "C:\Users\candon001\AppData\Local\Programs\Python\Python39\lib\site-packages\rest_framework\views.py", line 423, in finalize_response
    assert isinstance(response, HttpResponseBase), (
AssertionError: Expected a `Response`, `HttpResponse` or `HttpStreamingResponse` to be returned from the view, but received a `<class 'NoneType'>`
INFO 2022-06-02 18:59:32,673 - Validating user information by GUID
DEBUG 2022-06-02 18:59:32,675 - Starting new HTTPS connection (1): gumapiservice.pwcinternal.com:443
DEBUG 2022-06-02 18:59:35,339 - https://gumapiservice.pwcinternal.com:443 "POST /GumService.asmx?wsdl HTTP/1.1" 200 1035
ERROR 2022-06-02 18:59:35,468 - Internal Server Error: /api/post_user
Traceback (most recent call last):
  File "C:\Users\candon001\AppData\Local\Programs\Python\Python39\lib\site-packages\django\core\handlers\exception.py", line 47, in inner
    response = get_response(request)
  File "C:\Users\candon001\AppData\Local\Programs\Python\Python39\lib\site-packages\django\core\handlers\base.py", line 181, in _get_response
    response = wrapped_callback(request, *callback_args, **callback_kwargs)
  File "C:\Users\candon001\AppData\Local\Programs\Python\Python39\lib\site-packages\django\views\decorators\csrf.py", line 54, in wrapped_view
    return view_func(*args, **kwargs)
  File "C:\Users\candon001\AppData\Local\Programs\Python\Python39\lib\site-packages\django\views\decorators\csrf.py", line 54, in wrapped_view
    return view_func(*args, **kwargs)
  File "C:\Users\candon001\AppData\Local\Programs\Python\Python39\lib\site-packages\django\views\generic\base.py", line 70, in view
    return self.dispatch(request, *args, **kwargs)
  File "C:\Users\candon001\AppData\Local\Programs\Python\Python39\lib\site-packages\rest_framework\views.py", line 511, in dispatch
    self.response = self.finalize_response(request, response, *args, **kwargs)
  File "C:\Users\candon001\AppData\Local\Programs\Python\Python39\lib\site-packages\rest_framework\views.py", line 423, in finalize_response
    assert isinstance(response, HttpResponseBase), (
AssertionError: Expected a `Response`, `HttpResponse` or `HttpStreamingResponse` to be returned from the view, but received a `<class 'NoneType'>`
INFO 2022-06-02 23:15:00,186 - C:\DevOpsTools_Automation\Automation%20Platform\DVT_api\views.py changed, reloading.
DEBUG 2022-06-02 23:15:00,195 - Using proactor: IocpProactor
INFO 2022-06-02 23:15:03,213 - Watching for file changes with StatReloader
INFO 2022-06-02 23:16:12,607 - C:\DevOpsTools_Automation\Automation%20Platform\DVT_api\views.py changed, reloading.
DEBUG 2022-06-02 23:16:12,609 - Using proactor: IocpProactor
INFO 2022-06-02 23:16:15,210 - Watching for file changes with StatReloader
INFO 2022-06-02 23:18:34,588 - C:\DevOpsTools_Automation\Automation%20Platform\DVT_api\views.py changed, reloading.
DEBUG 2022-06-02 23:18:34,589 - Using proactor: IocpProactor
INFO 2022-06-02 23:18:36,285 - Watching for file changes with StatReloader
INFO 2022-06-02 23:19:15,717 - C:\DevOpsTools_Automation\Automation%20Platform\DVT_api\views.py changed, reloading.
DEBUG 2022-06-02 23:19:15,718 - Using proactor: IocpProactor
INFO 2022-06-02 23:19:17,607 - Watching for file changes with StatReloader
INFO 2022-06-02 23:20:31,248 - Validating GUID: garchibald002
DEBUG 2022-06-02 23:20:31,255 - Starting new HTTPS connection (1): gumapiservice.pwcinternal.com:443
DEBUG 2022-06-02 23:20:33,699 - https://gumapiservice.pwcinternal.com:443 "POST /GumService.asmx?wsdl HTTP/1.1" 200 1046
ERROR 2022-06-02 23:20:33,879 - Internal Server Error: /api/post_user
Traceback (most recent call last):
  File "C:\Users\candon001\AppData\Local\Programs\Python\Python39\lib\site-packages\django\core\handlers\exception.py", line 47, in inner
    response = get_response(request)
  File "C:\Users\candon001\AppData\Local\Programs\Python\Python39\lib\site-packages\django\core\handlers\base.py", line 181, in _get_response
    response = wrapped_callback(request, *callback_args, **callback_kwargs)
  File "C:\Users\candon001\AppData\Local\Programs\Python\Python39\lib\site-packages\django\views\decorators\csrf.py", line 54, in wrapped_view
    return view_func(*args, **kwargs)
  File "C:\Users\candon001\AppData\Local\Programs\Python\Python39\lib\site-packages\django\views\decorators\csrf.py", line 54, in wrapped_view
    return view_func(*args, **kwargs)
  File "C:\Users\candon001\AppData\Local\Programs\Python\Python39\lib\site-packages\django\views\generic\base.py", line 70, in view
    return self.dispatch(request, *args, **kwargs)
  File "C:\Users\candon001\AppData\Local\Programs\Python\Python39\lib\site-packages\rest_framework\views.py", line 511, in dispatch
    self.response = self.finalize_response(request, response, *args, **kwargs)
  File "C:\Users\candon001\AppData\Local\Programs\Python\Python39\lib\site-packages\rest_framework\views.py", line 423, in finalize_response
    assert isinstance(response, HttpResponseBase), (
AssertionError: Expected a `Response`, `HttpResponse` or `HttpStreamingResponse` to be returned from the view, but received a `<class 'NoneType'>`
DEBUG 2022-06-13 13:36:12,477 - Using proactor: IocpProactor
DEBUG 2022-06-13 13:36:13,025 - Using proactor: IocpProactor
INFO 2022-06-13 13:36:21,955 - Watching for file changes with StatReloader
WARNING 2022-06-13 13:36:31,228 - Not Found: /
INFO 2022-07-12 15:11:10,573 - Watching for file changes with StatReloader
DEBUG 2022-07-12 15:11:11,160 - Starting new HTTPS connection (1): api.pwc.com:443
DEBUG 2022-07-12 15:11:16,044 - https://api.pwc.com:443 "POST /pwcnetwork/service_now/api/ipwc/request_item/create/d954573ddbe53340a416f5261d9619c0/ritm_nv HTTP/1.1" 201 137
INFO 2022-07-12 15:11:16,050 - RITM RITM8954921 was created...
DEBUG 2022-07-12 15:11:16,055 - Starting new HTTPS connection (1): api.pwc.com:443
DEBUG 2022-07-12 15:11:17,015 - https://api.pwc.com:443 "GET /pwcnetwork/service_now/api/now/table/sc_task?sysparm_query=active%3Dtrue%5Erequest_item.number%3DRITM8954921&sysparm_fields=sys_id,number HTTP/1.1" 200 103
DEBUG 2022-07-12 15:11:18,835 - https://api.pwc.com:443 "PATCH /pwcnetwork/service_now/api/now/table/sc_task/079c1b871ba05d589bfe859ee54bcb0e HTTP/1.1" 200 1063
WARNING 2022-07-12 15:15:17,934 - Unauthorized: /api/post_user
WARNING 2022-07-12 15:16:19,251 - Not Found: /
WARNING 2022-07-12 15:16:19,454 - Not Found: /favicon.ico
ERROR 2022-07-12 15:17:08,595 - Internal Server Error: /api/post_user
Traceback (most recent call last):
  File "C:\Users\candon001\AppData\Local\Programs\Python\Python39\lib\site-packages\django\core\handlers\exception.py", line 47, in inner
    response = get_response(request)
  File "C:\Users\candon001\AppData\Local\Programs\Python\Python39\lib\site-packages\django\core\handlers\base.py", line 181, in _get_response
    response = wrapped_callback(request, *callback_args, **callback_kwargs)
  File "C:\Users\candon001\AppData\Local\Programs\Python\Python39\lib\site-packages\django\views\decorators\csrf.py", line 54, in wrapped_view
    return view_func(*args, **kwargs)
  File "C:\Users\candon001\AppData\Local\Programs\Python\Python39\lib\site-packages\django\views\decorators\csrf.py", line 54, in wrapped_view
    return view_func(*args, **kwargs)
  File "C:\Users\candon001\AppData\Local\Programs\Python\Python39\lib\site-packages\django\views\generic\base.py", line 70, in view
    return self.dispatch(request, *args, **kwargs)
  File "C:\Users\candon001\AppData\Local\Programs\Python\Python39\lib\site-packages\rest_framework\views.py", line 509, in dispatch
    response = self.handle_exception(exc)
  File "C:\Users\candon001\AppData\Local\Programs\Python\Python39\lib\site-packages\rest_framework\views.py", line 469, in handle_exception
    self.raise_uncaught_exception(exc)
  File "C:\Users\candon001\AppData\Local\Programs\Python\Python39\lib\site-packages\rest_framework\views.py", line 480, in raise_uncaught_exception
    raise exc
  File "C:\Users\candon001\AppData\Local\Programs\Python\Python39\lib\site-packages\rest_framework\views.py", line 506, in dispatch
    response = handler(request, *args, **kwargs)
  File "C:\Users\candon001\AppData\Local\Programs\Python\Python39\lib\site-packages\rest_framework\decorators.py", line 50, in handler
    return func(*args, **kwargs)
  File "C:\DevOpsTools_Automation\Automation%20Platform\DVT_api\views.py", line 63, in post_user
    guid = serializer.validated_data['guid']
  File "C:\Users\candon001\AppData\Local\Programs\Python\Python39\lib\site-packages\rest_framework\serializers.py", line 271, in validated_data
    raise AssertionError(msg)
AssertionError: You must call `.is_valid()` before accessing `.validated_data`.
INFO 2022-07-12 15:19:56,697 - C:\DevOpsTools_Automation\Automation%20Platform\DVT_api\views.py changed, reloading.
DEBUG 2022-07-12 15:19:56,709 - Using proactor: IocpProactor
INFO 2022-07-12 15:19:58,298 - Watching for file changes with StatReloader
DEBUG 2022-07-12 15:19:58,777 - Starting new HTTPS connection (1): api.pwc.com:443
DEBUG 2022-07-12 15:20:02,216 - https://api.pwc.com:443 "POST /pwcnetwork/service_now/api/ipwc/request_item/create/d954573ddbe53340a416f5261d9619c0/ritm_nv HTTP/1.1" 201 138
INFO 2022-07-12 15:20:02,222 - RITM RITM8955040 was created...
DEBUG 2022-07-12 15:20:02,226 - Starting new HTTPS connection (1): api.pwc.com:443
DEBUG 2022-07-12 15:20:03,524 - https://api.pwc.com:443 "GET /pwcnetwork/service_now/api/now/table/sc_task?sysparm_query=active%3Dtrue%5Erequest_item.number%3DRITM8955040&sysparm_fields=sys_id,number HTTP/1.1" 200 103
DEBUG 2022-07-12 15:20:05,133 - https://api.pwc.com:443 "PATCH /pwcnetwork/service_now/api/now/table/sc_task/6f9e53071ba85d58f96c6282b24bcbf1 HTTP/1.1" 200 1064
ERROR 2022-07-12 15:20:30,827 - Internal Server Error: /api/post_user
Traceback (most recent call last):
  File "C:\Users\candon001\AppData\Local\Programs\Python\Python39\lib\site-packages\django\core\handlers\exception.py", line 47, in inner
    response = get_response(request)
  File "C:\Users\candon001\AppData\Local\Programs\Python\Python39\lib\site-packages\django\core\handlers\base.py", line 181, in _get_response
    response = wrapped_callback(request, *callback_args, **callback_kwargs)
  File "C:\Users\candon001\AppData\Local\Programs\Python\Python39\lib\site-packages\django\views\decorators\csrf.py", line 54, in wrapped_view
    return view_func(*args, **kwargs)
  File "C:\Users\candon001\AppData\Local\Programs\Python\Python39\lib\site-packages\django\views\decorators\csrf.py", line 54, in wrapped_view
    return view_func(*args, **kwargs)
  File "C:\Users\candon001\AppData\Local\Programs\Python\Python39\lib\site-packages\django\views\generic\base.py", line 70, in view
    return self.dispatch(request, *args, **kwargs)
  File "C:\Users\candon001\AppData\Local\Programs\Python\Python39\lib\site-packages\rest_framework\views.py", line 509, in dispatch
    response = self.handle_exception(exc)
  File "C:\Users\candon001\AppData\Local\Programs\Python\Python39\lib\site-packages\rest_framework\views.py", line 469, in handle_exception
    self.raise_uncaught_exception(exc)
  File "C:\Users\candon001\AppData\Local\Programs\Python\Python39\lib\site-packages\rest_framework\views.py", line 480, in raise_uncaught_exception
    raise exc
  File "C:\Users\candon001\AppData\Local\Programs\Python\Python39\lib\site-packages\rest_framework\views.py", line 506, in dispatch
    response = handler(request, *args, **kwargs)
  File "C:\Users\candon001\AppData\Local\Programs\Python\Python39\lib\site-packages\rest_framework\decorators.py", line 50, in handler
    return func(*args, **kwargs)
  File "C:\DevOpsTools_Automation\Automation%20Platform\DVT_api\views.py", line 84, in post_user
    logger.error(f"Invalid GUID: {guid}")
UnboundLocalError: local variable 'guid' referenced before assignment
INFO 2022-07-12 15:21:36,992 - C:\DevOpsTools_Automation\Automation%20Platform\DVT_api\views.py changed, reloading.
DEBUG 2022-07-12 15:21:36,993 - Using proactor: IocpProactor
INFO 2022-07-12 15:21:38,917 - Watching for file changes with StatReloader
DEBUG 2022-07-12 15:21:39,335 - Starting new HTTPS connection (1): api.pwc.com:443
DEBUG 2022-07-12 15:21:42,189 - https://api.pwc.com:443 "POST /pwcnetwork/service_now/api/ipwc/request_item/create/d954573ddbe53340a416f5261d9619c0/ritm_nv HTTP/1.1" 201 137
INFO 2022-07-12 15:21:42,195 - RITM RITM8955070 was created...
DEBUG 2022-07-12 15:21:42,199 - Starting new HTTPS connection (1): api.pwc.com:443
DEBUG 2022-07-12 15:21:42,761 - https://api.pwc.com:443 "GET /pwcnetwork/service_now/api/now/table/sc_task?sysparm_query=active%3Dtrue%5Erequest_item.number%3DRITM8955070&sysparm_fields=sys_id,number HTTP/1.1" 200 103
DEBUG 2022-07-12 15:21:43,960 - https://api.pwc.com:443 "PATCH /pwcnetwork/service_now/api/now/table/sc_task/cc0f134b1be8d598e05a4152b24bcb64 HTTP/1.1" 200 1062
ERROR 2022-07-12 15:21:56,859 - Invalid GUID.....
WARNING 2022-07-12 15:21:56,860 - Not Found: /api/post_user
INFO 2022-07-12 15:25:33,401 - C:\DevOpsTools_Automation\Automation%20Platform\DVT_api\views.py changed, reloading.
DEBUG 2022-07-12 15:25:33,402 - Using proactor: IocpProactor
INFO 2022-07-12 15:25:36,732 - Watching for file changes with StatReloader
DEBUG 2022-07-12 15:25:37,203 - Starting new HTTPS connection (1): api.pwc.com:443
DEBUG 2022-07-12 15:25:41,178 - https://api.pwc.com:443 "POST /pwcnetwork/service_now/api/ipwc/request_item/create/d954573ddbe53340a416f5261d9619c0/ritm_nv HTTP/1.1" 201 135
INFO 2022-07-12 15:25:41,181 - RITM RITM8955111 was created...
DEBUG 2022-07-12 15:25:41,183 - Starting new HTTPS connection (1): api.pwc.com:443
DEBUG 2022-07-12 15:25:41,953 - https://api.pwc.com:443 "GET /pwcnetwork/service_now/api/now/table/sc_task?sysparm_query=active%3Dtrue%5Erequest_item.number%3DRITM8955111&sysparm_fields=sys_id,number HTTP/1.1" 200 103
DEBUG 2022-07-12 15:25:43,407 - https://api.pwc.com:443 "PATCH /pwcnetwork/service_now/api/now/table/sc_task/4eef93cb1be855984d78cb75464bcb5f HTTP/1.1" 200 1067
ERROR 2022-07-12 15:25:53,399 - Invalid GUID.....
WARNING 2022-07-12 15:25:53,400 - Not Found: /api/post_user
INFO 2022-07-12 15:49:27,682 - C:\DevOpsTools_Automation\Automation%20Platform\DVT_api\views.py changed, reloading.
DEBUG 2022-07-12 15:49:27,683 - Using proactor: IocpProactor
INFO 2022-07-12 15:49:30,205 - Watching for file changes with StatReloader
DEBUG 2022-07-12 15:49:30,649 - Starting new HTTPS connection (1): api.pwc.com:443
DEBUG 2022-07-12 15:49:34,380 - https://api.pwc.com:443 "POST /pwcnetwork/service_now/api/ipwc/request_item/create/d954573ddbe53340a416f5261d9619c0/ritm_nv HTTP/1.1" 201 137
INFO 2022-07-12 15:49:34,382 - RITM RITM8955488 was created...
DEBUG 2022-07-12 15:49:34,384 - Starting new HTTPS connection (1): api.pwc.com:443
DEBUG 2022-07-12 15:49:35,600 - https://api.pwc.com:443 "GET /pwcnetwork/service_now/api/now/table/sc_task?sysparm_query=active%3Dtrue%5Erequest_item.number%3DRITM8955488&sysparm_fields=sys_id,number HTTP/1.1" 200 103
DEBUG 2022-07-12 15:49:37,179 - https://api.pwc.com:443 "PATCH /pwcnetwork/service_now/api/now/table/sc_task/006523431becd598e05a4152b24bcb97 HTTP/1.1" 200 1070
ERROR 2022-07-12 15:49:55,240 - Invalid GUID.....
WARNING 2022-07-12 15:49:55,241 - Not Found: /api/post_user
INFO 2022-07-12 15:51:24,763 - C:\DevOpsTools_Automation\Automation%20Platform\DVT_api\views.py changed, reloading.
DEBUG 2022-07-12 15:51:24,764 - Using proactor: IocpProactor
INFO 2022-07-12 15:51:26,305 - Watching for file changes with StatReloader
DEBUG 2022-07-12 15:51:26,744 - Starting new HTTPS connection (1): api.pwc.com:443
DEBUG 2022-07-12 15:51:30,387 - https://api.pwc.com:443 "POST /pwcnetwork/service_now/api/ipwc/request_item/create/d954573ddbe53340a416f5261d9619c0/ritm_nv HTTP/1.1" 201 137
INFO 2022-07-12 15:51:30,389 - RITM RITM8955534 was created...
DEBUG 2022-07-12 15:51:30,391 - Starting new HTTPS connection (1): api.pwc.com:443
DEBUG 2022-07-12 15:51:31,253 - https://api.pwc.com:443 "GET /pwcnetwork/service_now/api/now/table/sc_task?sysparm_query=active%3Dtrue%5Erequest_item.number%3DRITM8955534&sysparm_fields=sys_id,number HTTP/1.1" 200 103
DEBUG 2022-07-12 15:51:32,614 - https://api.pwc.com:443 "PATCH /pwcnetwork/service_now/api/now/table/sc_task/20d5230f1bec5d58f96c6282b24bcb80 HTTP/1.1" 200 1066
ERROR 2022-07-12 15:51:43,708 - Invalid GUID.....
WARNING 2022-07-12 15:51:43,709 - Not Found: /api/post_user
ERROR 2022-07-12 15:52:04,055 - Invalid GUID.....
WARNING 2022-07-12 15:52:04,055 - Not Found: /api/post_user
INFO 2022-07-12 15:52:50,853 - C:\DevOpsTools_Automation\Automation%20Platform\DVT_api\views.py changed, reloading.
DEBUG 2022-07-12 15:52:50,854 - Using proactor: IocpProactor
INFO 2022-07-12 15:52:52,575 - Watching for file changes with StatReloader
DEBUG 2022-07-12 15:52:53,020 - Starting new HTTPS connection (1): api.pwc.com:443
DEBUG 2022-07-12 15:52:55,931 - https://api.pwc.com:443 "POST /pwcnetwork/service_now/api/ipwc/request_item/create/d954573ddbe53340a416f5261d9619c0/ritm_nv HTTP/1.1" 201 137
INFO 2022-07-12 15:52:55,934 - RITM RITM8955548 was created...
DEBUG 2022-07-12 15:52:55,937 - Starting new HTTPS connection (1): api.pwc.com:443
DEBUG 2022-07-12 15:52:56,644 - https://api.pwc.com:443 "GET /pwcnetwork/service_now/api/now/table/sc_task?sysparm_query=active%3Dtrue%5Erequest_item.number%3DRITM8955548&sysparm_fields=sys_id,number HTTP/1.1" 200 103
DEBUG 2022-07-12 15:52:58,163 - https://api.pwc.com:443 "PATCH /pwcnetwork/service_now/api/now/table/sc_task/d9262f471becd598e05a4152b24bcb04 HTTP/1.1" 200 1062
INFO 2022-07-12 15:53:28,412 - C:\DevOpsTools_Automation\Automation%20Platform\DVT_api\SNow_API.py changed, reloading.
DEBUG 2022-07-12 15:53:28,413 - Using proactor: IocpProactor
INFO 2022-07-12 15:53:30,105 - Watching for file changes with StatReloader
ERROR 2022-07-12 15:53:43,434 - Invalid GUID.....
WARNING 2022-07-12 15:53:43,434 - Not Found: /api/post_user
INFO 2022-07-12 15:54:09,421 - C:\DevOpsTools_Automation\Automation%20Platform\DVT_api\views.py changed, reloading.
DEBUG 2022-07-12 15:54:09,424 - Using proactor: IocpProactor
INFO 2022-07-12 15:54:11,117 - Watching for file changes with StatReloader
INFO 2022-07-12 15:57:23,823 - C:\DevOpsTools_Automation\Automation%20Platform\DVT_api\views.py changed, reloading.
DEBUG 2022-07-12 15:57:23,824 - Using proactor: IocpProactor
INFO 2022-07-12 15:57:25,944 - Watching for file changes with StatReloader
ERROR 2022-07-12 15:57:56,347 - Invalid GUID.....
WARNING 2022-07-12 15:57:56,348 - Not Found: /api/post_user
WARNING 2022-07-12 16:01:05,430 - Method Not Allowed: /api/get_user
ERROR 2022-07-12 16:01:17,212 - Invalid GUID.....
WARNING 2022-07-12 16:01:17,213 - Not Found: /api/post_user
INFO 2022-07-12 16:07:15,482 - C:\DevOpsTools_Automation\Automation%20Platform\DVT_api\views.py changed, reloading.
DEBUG 2022-07-12 16:07:15,483 - Using proactor: IocpProactor
INFO 2022-07-12 16:07:16,993 - Watching for file changes with StatReloader
ERROR 2022-07-12 16:07:24,594 - Internal Server Error: /api/post_user
Traceback (most recent call last):
  File "C:\Users\candon001\AppData\Local\Programs\Python\Python39\lib\site-packages\django\core\handlers\exception.py", line 47, in inner
    response = get_response(request)
  File "C:\Users\candon001\AppData\Local\Programs\Python\Python39\lib\site-packages\django\core\handlers\base.py", line 181, in _get_response
    response = wrapped_callback(request, *callback_args, **callback_kwargs)
  File "C:\Users\candon001\AppData\Local\Programs\Python\Python39\lib\site-packages\django\views\decorators\csrf.py", line 54, in wrapped_view
    return view_func(*args, **kwargs)
  File "C:\Users\candon001\AppData\Local\Programs\Python\Python39\lib\site-packages\django\views\decorators\csrf.py", line 54, in wrapped_view
    return view_func(*args, **kwargs)
  File "C:\Users\candon001\AppData\Local\Programs\Python\Python39\lib\site-packages\django\views\generic\base.py", line 70, in view
    return self.dispatch(request, *args, **kwargs)
  File "C:\Users\candon001\AppData\Local\Programs\Python\Python39\lib\site-packages\rest_framework\views.py", line 509, in dispatch
    response = self.handle_exception(exc)
  File "C:\Users\candon001\AppData\Local\Programs\Python\Python39\lib\site-packages\rest_framework\views.py", line 469, in handle_exception
    self.raise_uncaught_exception(exc)
  File "C:\Users\candon001\AppData\Local\Programs\Python\Python39\lib\site-packages\rest_framework\views.py", line 480, in raise_uncaught_exception
    raise exc
  File "C:\Users\candon001\AppData\Local\Programs\Python\Python39\lib\site-packages\rest_framework\views.py", line 506, in dispatch
    response = handler(request, *args, **kwargs)
  File "C:\Users\candon001\AppData\Local\Programs\Python\Python39\lib\site-packages\rest_framework\decorators.py", line 50, in handler
    return func(*args, **kwargs)
  File "C:\DevOpsTools_Automation\Automation%20Platform\DVT_api\views.py", line 111, in post_user
    logger.error(f"Invalid GUID: {guid}")
UnboundLocalError: local variable 'guid' referenced before assignment
INFO 2022-07-12 16:07:55,287 - C:\DevOpsTools_Automation\Automation%20Platform\DVT_api\views.py changed, reloading.
DEBUG 2022-07-12 16:07:55,287 - Using proactor: IocpProactor
INFO 2022-07-12 16:07:56,922 - Watching for file changes with StatReloader
ERROR 2022-07-12 16:08:07,190 - Invalid GUID:
WARNING 2022-07-12 16:08:07,191 - Not Found: /api/post_user
INFO 2022-07-12 16:09:20,857 - C:\DevOpsTools_Automation\Automation%20Platform\DVT_api\views.py changed, reloading.
DEBUG 2022-07-12 16:09:20,858 - Using proactor: IocpProactor
INFO 2022-07-12 16:09:22,592 - Watching for file changes with StatReloader
ERROR 2022-07-12 16:09:26,209 - Internal Server Error: /api/post_user
Traceback (most recent call last):
  File "C:\Users\candon001\AppData\Local\Programs\Python\Python39\lib\site-packages\django\core\handlers\exception.py", line 47, in inner
    response = get_response(request)
  File "C:\Users\candon001\AppData\Local\Programs\Python\Python39\lib\site-packages\django\core\handlers\base.py", line 181, in _get_response
    response = wrapped_callback(request, *callback_args, **callback_kwargs)
  File "C:\Users\candon001\AppData\Local\Programs\Python\Python39\lib\site-packages\django\views\decorators\csrf.py", line 54, in wrapped_view
    return view_func(*args, **kwargs)
  File "C:\Users\candon001\AppData\Local\Programs\Python\Python39\lib\site-packages\django\views\decorators\csrf.py", line 54, in wrapped_view
    return view_func(*args, **kwargs)
  File "C:\Users\candon001\AppData\Local\Programs\Python\Python39\lib\site-packages\django\views\generic\base.py", line 70, in view
    return self.dispatch(request, *args, **kwargs)
  File "C:\Users\candon001\AppData\Local\Programs\Python\Python39\lib\site-packages\rest_framework\views.py", line 509, in dispatch
    response = self.handle_exception(exc)
  File "C:\Users\candon001\AppData\Local\Programs\Python\Python39\lib\site-packages\rest_framework\views.py", line 469, in handle_exception
    self.raise_uncaught_exception(exc)
  File "C:\Users\candon001\AppData\Local\Programs\Python\Python39\lib\site-packages\rest_framework\views.py", line 480, in raise_uncaught_exception
    raise exc
  File "C:\Users\candon001\AppData\Local\Programs\Python\Python39\lib\site-packages\rest_framework\views.py", line 506, in dispatch
    response = handler(request, *args, **kwargs)
  File "C:\Users\candon001\AppData\Local\Programs\Python\Python39\lib\site-packages\rest_framework\decorators.py", line 50, in handler
    return func(*args, **kwargs)
  File "C:\DevOpsTools_Automation\Automation%20Platform\DVT_api\views.py", line 104, in post_user
    if serializer.is_valid():
UnboundLocalError: local variable 'serializer' referenced before assignment
DEBUG 2022-07-12 16:28:40,872 - Using proactor: IocpProactor
DEBUG 2022-07-12 16:28:41,005 - Using proactor: IocpProactor
INFO 2022-07-12 16:30:24,367 - Watching for file changes with StatReloader
ERROR 2022-07-12 16:30:36,011 - Internal Server Error: /api/post_user
Traceback (most recent call last):
  File "C:\Users\candon001\AppData\Local\Programs\Python\Python39\lib\site-packages\django\core\handlers\exception.py", line 47, in inner
    response = get_response(request)
  File "C:\Users\candon001\AppData\Local\Programs\Python\Python39\lib\site-packages\django\core\handlers\base.py", line 181, in _get_response
    response = wrapped_callback(request, *callback_args, **callback_kwargs)
  File "C:\Users\candon001\AppData\Local\Programs\Python\Python39\lib\site-packages\django\views\decorators\csrf.py", line 54, in wrapped_view
    return view_func(*args, **kwargs)
  File "C:\Users\candon001\AppData\Local\Programs\Python\Python39\lib\site-packages\django\views\decorators\csrf.py", line 54, in wrapped_view
    return view_func(*args, **kwargs)
  File "C:\Users\candon001\AppData\Local\Programs\Python\Python39\lib\site-packages\django\views\generic\base.py", line 70, in view
    return self.dispatch(request, *args, **kwargs)
  File "C:\Users\candon001\AppData\Local\Programs\Python\Python39\lib\site-packages\rest_framework\views.py", line 509, in dispatch
    response = self.handle_exception(exc)
  File "C:\Users\candon001\AppData\Local\Programs\Python\Python39\lib\site-packages\rest_framework\views.py", line 469, in handle_exception
    self.raise_uncaught_exception(exc)
  File "C:\Users\candon001\AppData\Local\Programs\Python\Python39\lib\site-packages\rest_framework\views.py", line 480, in raise_uncaught_exception
    raise exc
  File "C:\Users\candon001\AppData\Local\Programs\Python\Python39\lib\site-packages\rest_framework\views.py", line 506, in dispatch
    response = handler(request, *args, **kwargs)
  File "C:\Users\candon001\AppData\Local\Programs\Python\Python39\lib\site-packages\rest_framework\decorators.py", line 50, in handler
    return func(*args, **kwargs)
  File "C:\Users\candon001\Automation%20Platform\DVT_api\views.py", line 68, in post_user
    logger.error(f"Invalid GUID: {guid}")
UnboundLocalError: local variable 'guid' referenced before assignment
INFO 2022-07-12 16:30:53,450 - C:\Users\candon001\Automation%20Platform\DVT_api\views.py changed, reloading.
DEBUG 2022-07-12 16:30:53,450 - Using proactor: IocpProactor
INFO 2022-07-12 16:30:55,306 - Watching for file changes with StatReloader
ERROR 2022-07-12 16:30:59,635 - Invalid GUID:
WARNING 2022-07-12 16:30:59,636 - Not Found: /api/post_user
ERROR 2022-07-12 16:32:03,944 - Invalid GUID:
WARNING 2022-07-12 16:32:03,944 - Not Found: /api/post_user
ERROR 2022-07-12 16:32:56,962 - Invalid GUID:
WARNING 2022-07-12 16:32:56,963 - Not Found: /api/post_user
ERROR 2022-07-12 16:33:27,806 - Invalid GUID:
WARNING 2022-07-12 16:33:27,807 - Not Found: /api/post_user
WARNING 2022-07-12 16:38:04,382 - Unauthorized: /api/get_user
ERROR 2022-07-12 16:39:51,037 - Invalid GUID:
WARNING 2022-07-12 16:39:51,038 - Not Found: /api/post_user
ERROR 2022-07-12 16:40:00,701 - Invalid GUID:
WARNING 2022-07-12 16:40:00,701 - Not Found: /api/post_user
INFO 2022-07-12 16:42:47,941 - C:\Users\candon001\Automation%20Platform\DVT_api\views.py changed, reloading.
DEBUG 2022-07-12 16:42:47,942 - Using proactor: IocpProactor
INFO 2022-07-12 16:42:49,530 - Watching for file changes with StatReloader
ERROR 2022-07-12 16:42:55,673 - Invalid GUID:
WARNING 2022-07-12 16:42:55,674 - Not Found: /api/post_user
ERROR 2022-07-12 16:43:17,239 - Invalid GUID:
WARNING 2022-07-12 16:43:17,239 - Not Found: /api/post_user
ERROR 2022-07-12 16:43:55,155 - Invalid GUID:
WARNING 2022-07-12 16:43:55,155 - Not Found: /api/post_user
INFO 2022-07-12 16:46:14,064 - C:\Users\candon001\Automation%20Platform\DVT_api\views.py changed, reloading.
DEBUG 2022-07-12 16:46:14,065 - Using proactor: IocpProactor
INFO 2022-07-12 16:46:15,524 - Watching for file changes with StatReloader
WARNING 2022-07-12 16:46:25,956 - Bad Request: /api/post_user
INFO 2022-07-12 16:49:46,194 - C:\Users\candon001\Automation%20Platform\DVT_api\views.py changed, reloading.
DEBUG 2022-07-12 16:49:46,195 - Using proactor: IocpProactor
INFO 2022-07-12 16:49:47,652 - Watching for file changes with StatReloader
ERROR 2022-07-12 16:49:55,514 - Invalid GUID:
WARNING 2022-07-12 16:49:55,515 - Not Found: /api/post_user
INFO 2022-07-12 16:51:16,686 - C:\Users\candon001\Automation%20Platform\DVT_api\views.py changed, reloading.
DEBUG 2022-07-12 16:51:16,686 - Using proactor: IocpProactor
INFO 2022-07-12 16:51:18,298 - Watching for file changes with StatReloader
ERROR 2022-07-12 16:51:25,376 - Invalid GUID:
WARNING 2022-07-12 16:51:25,377 - Not Found: /api/post_user
INFO 2022-07-12 16:52:28,120 - C:\Users\candon001\Automation%20Platform\DVT_api\views.py changed, reloading.
DEBUG 2022-07-12 16:52:28,120 - Using proactor: IocpProactor
INFO 2022-07-12 16:52:29,624 - Watching for file changes with StatReloader
ERROR 2022-07-12 16:52:33,612 - Invalid GUID:
WARNING 2022-07-12 16:52:33,613 - Not Found: /api/post_user
ERROR 2022-07-12 16:52:42,123 - Invalid GUID:
WARNING 2022-07-12 16:52:42,123 - Not Found: /api/post_user
INFO 2022-07-12 16:53:43,717 - C:\Users\candon001\Automation%20Platform\DVT_api\views.py changed, reloading.
DEBUG 2022-07-12 16:53:43,718 - Using proactor: IocpProactor
INFO 2022-07-12 16:53:45,256 - Watching for file changes with StatReloader
WARNING 2022-07-12 16:53:49,343 - Bad Request: /api/post_user
INFO 2022-07-12 16:55:30,288 - C:\Users\candon001\Automation%20Platform\DVT_api\views.py changed, reloading.
DEBUG 2022-07-12 16:55:30,289 - Using proactor: IocpProactor
INFO 2022-07-12 16:55:32,224 - Watching for file changes with StatReloader
WARNING 2022-07-12 16:55:36,074 - Not Found: /api/post_user
INFO 2022-07-12 16:56:55,846 - C:\Users\candon001\Automation%20Platform\DVT_api\views.py changed, reloading.
DEBUG 2022-07-12 16:56:55,847 - Using proactor: IocpProactor
INFO 2022-07-12 16:56:57,943 - Watching for file changes with StatReloader
WARNING 2022-07-12 16:57:04,266 - Bad Request: /api/post_user
DEBUG 2022-07-12 17:01:12,178 - Using proactor: IocpProactor
DEBUG 2022-07-12 17:01:12,314 - Using proactor: IocpProactor
INFO 2022-07-12 17:03:12,495 - Watching for file changes with StatReloader
INFO 2022-07-12 17:03:53,907 - C:\DevOpsTools_Automation\Automation%20Platform\DVT_api\views.py changed, reloading.
DEBUG 2022-07-12 17:03:53,907 - Using proactor: IocpProactor
INFO 2022-07-12 17:03:55,568 - Watching for file changes with StatReloader
WARNING 2022-07-12 17:04:00,496 - Bad Request: /api/post_user
INFO 2022-07-12 17:04:57,839 - Validating GUID: rbularca
DEBUG 2022-07-12 17:04:57,845 - Starting new HTTPS connection (1): gumapiservice.pwcinternal.com:443
DEBUG 2022-07-12 17:04:59,862 - https://gumapiservice.pwcinternal.com:443 "POST /GumService.asmx?wsdl HTTP/1.1" 200 486
ERROR 2022-07-12 17:05:00,045 - Internal Server Error: /api/post_user
Traceback (most recent call last):
  File "C:\Users\candon001\AppData\Local\Programs\Python\Python39\lib\site-packages\django\core\handlers\exception.py", line 47, in inner
    response = get_response(request)
  File "C:\Users\candon001\AppData\Local\Programs\Python\Python39\lib\site-packages\django\core\handlers\base.py", line 181, in _get_response
    response = wrapped_callback(request, *callback_args, **callback_kwargs)
  File "C:\Users\candon001\AppData\Local\Programs\Python\Python39\lib\site-packages\django\views\decorators\csrf.py", line 54, in wrapped_view
    return view_func(*args, **kwargs)
  File "C:\Users\candon001\AppData\Local\Programs\Python\Python39\lib\site-packages\django\views\decorators\csrf.py", line 54, in wrapped_view
    return view_func(*args, **kwargs)
  File "C:\Users\candon001\AppData\Local\Programs\Python\Python39\lib\site-packages\django\views\generic\base.py", line 70, in view
    return self.dispatch(request, *args, **kwargs)
  File "C:\Users\candon001\AppData\Local\Programs\Python\Python39\lib\site-packages\rest_framework\views.py", line 509, in dispatch
    response = self.handle_exception(exc)
  File "C:\Users\candon001\AppData\Local\Programs\Python\Python39\lib\site-packages\rest_framework\views.py", line 469, in handle_exception
    self.raise_uncaught_exception(exc)
  File "C:\Users\candon001\AppData\Local\Programs\Python\Python39\lib\site-packages\rest_framework\views.py", line 480, in raise_uncaught_exception
    raise exc
  File "C:\Users\candon001\AppData\Local\Programs\Python\Python39\lib\site-packages\rest_framework\views.py", line 506, in dispatch
    response = handler(request, *args, **kwargs)
  File "C:\Users\candon001\AppData\Local\Programs\Python\Python39\lib\site-packages\rest_framework\decorators.py", line 50, in handler
    return func(*args, **kwargs)
  File "C:\DevOpsTools_Automation\Automation%20Platform\DVT_api\views.py", line 115, in post_user
    serializer.save()
  File "C:\Users\candon001\AppData\Local\Programs\Python\Python39\lib\site-packages\rest_framework\serializers.py", line 212, in save
    self.instance = self.create(validated_data)
  File "C:\Users\candon001\AppData\Local\Programs\Python\Python39\lib\site-packages\rest_framework\serializers.py", line 962, in create
    instance = ModelClass._default_manager.create(**validated_data)
  File "C:\Users\candon001\AppData\Local\Programs\Python\Python39\lib\site-packages\django\db\models\manager.py", line 85, in manager_method
    return getattr(self.get_queryset(), name)(*args, **kwargs)
  File "C:\Users\candon001\AppData\Local\Programs\Python\Python39\lib\site-packages\django\db\models\query.py", line 453, in create
    obj.save(force_insert=True, using=self.db)
  File "C:\DevOpsTools_Automation\Automation%20Platform\DVT_api\models.py", line 44, in save
    self.email_address = children1[1][3].text
  File "src\lxml\etree.pyx", line 1161, in lxml.etree._Element.__getitem__
IndexError: list index out of range
INFO 2022-07-12 17:06:32,986 - Validating GUID: candon001
DEBUG 2022-07-12 17:06:32,987 - Starting new HTTPS connection (1): gumapiservice.pwcinternal.com:443
DEBUG 2022-07-12 17:06:35,267 - https://gumapiservice.pwcinternal.com:443 "POST /GumService.asmx?wsdl HTTP/1.1" 200 1035
INFO 2022-07-12 17:09:17,291 - C:\DevOpsTools_Automation\Automation%20Platform\DVT_api\views.py changed, reloading.
DEBUG 2022-07-12 17:09:17,292 - Using proactor: IocpProactor
INFO 2022-07-12 17:09:19,421 - Watching for file changes with StatReloader
INFO 2022-07-12 17:09:23,154 - Validating GUID: candon001
DEBUG 2022-07-12 17:09:23,157 - Starting new HTTPS connection (1): gumapiservice.pwcinternal.com:443
DEBUG 2022-07-12 17:09:25,104 - https://gumapiservice.pwcinternal.com:443 "POST /GumService.asmx?wsdl HTTP/1.1" 200 1035
INFO 2022-07-12 17:10:11,529 - C:\DevOpsTools_Automation\Automation%20Platform\DVT_api\views.py changed, reloading.
DEBUG 2022-07-12 17:10:11,530 - Using proactor: IocpProactor
INFO 2022-07-12 17:10:13,145 - Watching for file changes with StatReloader
INFO 2022-07-12 17:10:19,410 - Validating GUID: candon001
DEBUG 2022-07-12 17:10:19,418 - Starting new HTTPS connection (1): gumapiservice.pwcinternal.com:443
DEBUG 2022-07-12 17:10:21,588 - https://gumapiservice.pwcinternal.com:443 "POST /GumService.asmx?wsdl HTTP/1.1" 200 1035
INFO 2022-07-12 17:11:30,938 - C:\DevOpsTools_Automation\Automation%20Platform\DVT_api\views.py changed, reloading.
DEBUG 2022-07-12 17:11:30,939 - Using proactor: IocpProactor
INFO 2022-07-12 17:11:32,650 - Watching for file changes with StatReloader
INFO 2022-07-12 17:11:41,249 - Validating GUID: candon001
DEBUG 2022-07-12 17:11:41,253 - Starting new HTTPS connection (1): gumapiservice.pwcinternal.com:443
DEBUG 2022-07-12 17:11:43,302 - https://gumapiservice.pwcinternal.com:443 "POST /GumService.asmx?wsdl HTTP/1.1" 200 1035
INFO 2022-07-12 17:14:37,404 - C:\DevOpsTools_Automation\Automation%20Platform\DVT_api\views.py changed, reloading.
DEBUG 2022-07-12 17:14:37,405 - Using proactor: IocpProactor
INFO 2022-07-12 17:14:39,672 - Watching for file changes with StatReloader
INFO 2022-07-12 17:14:45,068 - Validating GUID: candon001
DEBUG 2022-07-12 17:14:45,072 - Starting new HTTPS connection (1): gumapiservice.pwcinternal.com:443
DEBUG 2022-07-12 17:14:47,051 - https://gumapiservice.pwcinternal.com:443 "POST /GumService.asmx?wsdl HTTP/1.1" 200 1035
INFO 2022-07-12 17:26:07,525 - C:\DevOpsTools_Automation\Automation%20Platform\DVT_api\SNow_API.py changed, reloading.
DEBUG 2022-07-12 17:26:07,528 - Using proactor: IocpProactor
INFO 2022-07-12 17:26:10,727 - Watching for file changes with StatReloader
INFO 2022-07-12 17:26:22,088 - Validating GUID: candon001
DEBUG 2022-07-12 17:26:22,092 - Starting new HTTPS connection (1): gumapiservice.pwcinternal.com:443
DEBUG 2022-07-12 17:26:24,172 - https://gumapiservice.pwcinternal.com:443 "POST /GumService.asmx?wsdl HTTP/1.1" 200 1035
INFO 2022-07-12 17:28:27,525 - C:\DevOpsTools_Automation\Automation%20Platform\DVT_api\SNow_API.py changed, reloading.
DEBUG 2022-07-12 17:28:27,526 - Using proactor: IocpProactor
INFO 2022-07-12 17:28:29,979 - Watching for file changes with StatReloader
INFO 2022-07-12 17:28:36,684 - Validating GUID: candon001
DEBUG 2022-07-12 17:28:36,687 - Starting new HTTPS connection (1): gumapiservice.pwcinternal.com:443
DEBUG 2022-07-12 17:28:38,918 - https://gumapiservice.pwcinternal.com:443 "POST /GumService.asmx?wsdl HTTP/1.1" 200 1035
INFO 2022-07-12 17:34:50,538 - Validating GUID: ftanasa001
DEBUG 2022-07-12 17:34:50,539 - Starting new HTTPS connection (1): gumapiservice.pwcinternal.com:443
DEBUG 2022-07-12 17:34:53,256 - https://gumapiservice.pwcinternal.com:443 "POST /GumService.asmx?wsdl HTTP/1.1" 200 1035
INFO 2022-07-12 17:44:09,782 - C:\DevOpsTools_Automation\Automation%20Platform\DVT_api\views.py changed, reloading.
DEBUG 2022-07-12 17:44:09,783 - Using proactor: IocpProactor
INFO 2022-07-12 17:44:13,163 - Watching for file changes with StatReloader
INFO 2022-07-12 17:44:19,791 - Validating GUID: ftanasa001
DEBUG 2022-07-12 17:44:19,797 - Starting new HTTPS connection (1): gumapiservice.pwcinternal.com:443
DEBUG 2022-07-12 17:44:21,651 - https://gumapiservice.pwcinternal.com:443 "POST /GumService.asmx?wsdl HTTP/1.1" 200 1035
INFO 2022-07-12 17:50:38,690 - C:\DevOpsTools_Automation\Automation%20Platform\DVT_api\views.py changed, reloading.
DEBUG 2022-07-12 17:50:38,691 - Using proactor: IocpProactor
INFO 2022-07-12 17:50:40,560 - Watching for file changes with StatReloader
INFO 2022-07-12 17:50:52,397 - Validating GUID: ftanasa001
DEBUG 2022-07-12 17:50:52,401 - Starting new HTTPS connection (1): gumapiservice.pwcinternal.com:443
DEBUG 2022-07-12 17:50:54,567 - https://gumapiservice.pwcinternal.com:443 "POST /GumService.asmx?wsdl HTTP/1.1" 200 1035
INFO 2022-07-12 17:52:43,486 - Watching for file changes with StatReloader
INFO 2022-07-12 17:52:52,187 - Validating GUID: ftanasa001
DEBUG 2022-07-12 17:52:52,196 - Starting new HTTPS connection (1): gumapiservice.pwcinternal.com:443
DEBUG 2022-07-12 17:52:54,175 - https://gumapiservice.pwcinternal.com:443 "POST /GumService.asmx?wsdl HTTP/1.1" 200 1035
INFO 2022-07-12 17:55:54,560 - C:\DevOpsTools_Automation\Automation%20Platform\DVT_api\views.py changed, reloading.
DEBUG 2022-07-12 17:55:54,561 - Using proactor: IocpProactor
INFO 2022-07-12 17:55:56,521 - Watching for file changes with StatReloader
INFO 2022-07-12 17:56:06,592 - Validating GUID: ftanasa001
DEBUG 2022-07-12 17:56:06,596 - Starting new HTTPS connection (1): gumapiservice.pwcinternal.com:443
DEBUG 2022-07-12 17:56:09,283 - https://gumapiservice.pwcinternal.com:443 "POST /GumService.asmx?wsdl HTTP/1.1" 200 1035
INFO 2022-07-12 17:59:27,069 - C:\DevOpsTools_Automation\Automation%20Platform\DVT_api\views.py changed, reloading.
DEBUG 2022-07-12 17:59:27,070 - Using proactor: IocpProactor
INFO 2022-07-12 17:59:30,074 - Watching for file changes with StatReloader
INFO 2022-07-12 18:00:31,108 - C:\DevOpsTools_Automation\Automation%20Platform\DVT_api\views.py changed, reloading.
DEBUG 2022-07-12 18:00:31,109 - Using proactor: IocpProactor
INFO 2022-07-12 18:00:33,820 - Watching for file changes with StatReloader
INFO 2022-07-12 18:02:27,221 - C:\DevOpsTools_Automation\Automation%20Platform\DVT_api\views.py changed, reloading.
DEBUG 2022-07-12 18:02:27,222 - Using proactor: IocpProactor
INFO 2022-07-12 18:02:29,545 - Watching for file changes with StatReloader
INFO 2022-07-12 18:03:08,339 - Validating GUID: ftanasa001
DEBUG 2022-07-12 18:03:08,344 - Starting new HTTPS connection (1): gumapiservice.pwcinternal.com:443
DEBUG 2022-07-12 18:03:10,594 - https://gumapiservice.pwcinternal.com:443 "POST /GumService.asmx?wsdl HTTP/1.1" 200 1035
INFO 2022-07-12 18:03:10,596 - Preparing data for Service Now process!
INFO 2022-07-12 18:03:10,604 - User has no Service Now RITM, creating a new one.......
INFO 2022-07-12 18:03:10,604 - Creating new RITM.....
DEBUG 2022-07-12 18:03:10,606 - Starting new HTTPS connection (1): api.pwc.com:443
DEBUG 2022-07-12 18:03:15,184 - https://api.pwc.com:443 "POST /pwcnetwork/service_now/api/ipwc/request_item/create/d954573ddbe53340a416f5261d9619c0/ritm_nv HTTP/1.1" 201 137
INFO 2022-07-12 18:03:15,190 - RITM RITM8957766 was created...
DEBUG 2022-07-12 18:03:15,193 - Starting new HTTPS connection (1): api.pwc.com:443
DEBUG 2022-07-12 18:03:17,194 - https://api.pwc.com:443 "GET /pwcnetwork/service_now/api/now/table/sc_task?sysparm_query=active%3Dtrue%5Erequest_item.number%3DRITM8957766&sysparm_fields=sys_id,number HTTP/1.1" 200 103
INFO 2022-07-12 18:03:17,202 - User checked and saved...
DEBUG 2022-07-12 18:05:58,614 - Using proactor: IocpProactor
DEBUG 2022-07-12 18:05:58,773 - Using proactor: IocpProactor
INFO 2022-07-12 18:06:06,247 - Watching for file changes with StatReloader
INFO 2022-07-12 18:08:00,745 - Validating GUID: rburlaca001
DEBUG 2022-07-12 18:08:00,855 - Starting new HTTPS connection (1): gumapiservice.pwcinternal.com:443
DEBUG 2022-07-12 18:08:03,235 - https://gumapiservice.pwcinternal.com:443 "POST /GumService.asmx?wsdl HTTP/1.1" 200 486
INFO 2022-07-12 18:08:03,257 - Preparing data for Service Now process!
ERROR 2022-07-12 18:08:06,927 - Internal Server Error: /api/post_user
Traceback (most recent call last):
  File "C:\Users\candon001\AppData\Local\Programs\Python\Python39\lib\site-packages\django\core\handlers\exception.py", line 47, in inner
    response = get_response(request)
  File "C:\Users\candon001\AppData\Local\Programs\Python\Python39\lib\site-packages\django\core\handlers\base.py", line 181, in _get_response
    response = wrapped_callback(request, *callback_args, **callback_kwargs)
  File "C:\Users\candon001\AppData\Local\Programs\Python\Python39\lib\site-packages\django\views\decorators\csrf.py", line 54, in wrapped_view
    return view_func(*args, **kwargs)
  File "C:\Users\candon001\AppData\Local\Programs\Python\Python39\lib\site-packages\django\views\decorators\csrf.py", line 54, in wrapped_view
    return view_func(*args, **kwargs)
  File "C:\Users\candon001\AppData\Local\Programs\Python\Python39\lib\site-packages\django\views\generic\base.py", line 70, in view
    return self.dispatch(request, *args, **kwargs)
  File "C:\Users\candon001\AppData\Local\Programs\Python\Python39\lib\site-packages\rest_framework\views.py", line 509, in dispatch
    response = self.handle_exception(exc)
  File "C:\Users\candon001\AppData\Local\Programs\Python\Python39\lib\site-packages\rest_framework\views.py", line 469, in handle_exception
    self.raise_uncaught_exception(exc)
  File "C:\Users\candon001\AppData\Local\Programs\Python\Python39\lib\site-packages\rest_framework\views.py", line 480, in raise_uncaught_exception
    raise exc
  File "C:\Users\candon001\AppData\Local\Programs\Python\Python39\lib\site-packages\rest_framework\views.py", line 506, in dispatch
    response = handler(request, *args, **kwargs)
  File "C:\Users\candon001\AppData\Local\Programs\Python\Python39\lib\site-packages\rest_framework\decorators.py", line 50, in handler
    return func(*args, **kwargs)
  File "C:\DevOpsTools_Automation\Automation%20Platform\DVT_api\views.py", line 108, in post_user
    email_address = children1[1][3].text
  File "src\lxml\etree.pyx", line 1161, in lxml.etree._Element.__getitem__
IndexError: list index out of range
INFO 2022-07-12 18:09:24,360 - Validating GUID: rbularca001
DEBUG 2022-07-12 18:09:24,375 - Starting new HTTPS connection (1): gumapiservice.pwcinternal.com:443
DEBUG 2022-07-12 18:09:26,554 - https://gumapiservice.pwcinternal.com:443 "POST /GumService.asmx?wsdl HTTP/1.1" 200 1032
INFO 2022-07-12 18:09:26,562 - Preparing data for Service Now process!
INFO 2022-07-12 18:09:26,597 - User has no Service Now RITM, creating a new one.......
INFO 2022-07-12 18:09:26,600 - Creating new RITM.....
DEBUG 2022-07-12 18:09:26,608 - Starting new HTTPS connection (1): api.pwc.com:443
DEBUG 2022-07-12 18:09:30,709 - https://api.pwc.com:443 "POST /pwcnetwork/service_now/api/ipwc/request_item/create/d954573ddbe53340a416f5261d9619c0/ritm_nv HTTP/1.1" 201 138
INFO 2022-07-12 18:09:30,722 - RITM RITM8957865 was created...
DEBUG 2022-07-12 18:09:30,735 - Starting new HTTPS connection (1): api.pwc.com:443
DEBUG 2022-07-12 18:09:31,410 - https://api.pwc.com:443 "GET /pwcnetwork/service_now/api/now/table/sc_task?sysparm_query=active%3Dtrue%5Erequest_item.number%3DRITM8957865&sysparm_fields=sys_id,number HTTP/1.1" 200 103
INFO 2022-07-12 18:09:31,457 - User checked and saved...
INFO 2022-07-12 18:16:17,544 - C:\DevOpsTools_Automation\Automation%20Platform\DVT_api\views.py changed, reloading.
DEBUG 2022-07-12 18:16:17,544 - Using proactor: IocpProactor
INFO 2022-07-12 18:16:20,239 - Watching for file changes with StatReloader
INFO 2022-07-12 18:17:17,834 - Validating GUID: candon001
DEBUG 2022-07-12 18:17:17,837 - Starting new HTTPS connection (1): gumapiservice.pwcinternal.com:443
DEBUG 2022-07-12 18:17:20,208 - https://gumapiservice.pwcinternal.com:443 "POST /GumService.asmx?wsdl HTTP/1.1" 200 1035
INFO 2022-07-12 18:17:20,210 - Preparing data for Service Now process!
INFO 2022-07-12 18:17:20,218 - User has no Service Now RITM, creating a new one.......
INFO 2022-07-12 18:17:20,218 - Creating new RITM.....
DEBUG 2022-07-12 18:17:20,219 - Starting new HTTPS connection (1): api.pwc.com:443
DEBUG 2022-07-12 18:17:23,379 - https://api.pwc.com:443 "POST /pwcnetwork/service_now/api/ipwc/request_item/create/d954573ddbe53340a416f5261d9619c0/ritm_nv HTTP/1.1" 201 138
INFO 2022-07-12 18:17:23,381 - RITM RITM8957975 was created...
DEBUG 2022-07-12 18:17:23,383 - Starting new HTTPS connection (1): api.pwc.com:443
DEBUG 2022-07-12 18:17:24,245 - https://api.pwc.com:443 "GET /pwcnetwork/service_now/api/now/table/sc_task?sysparm_query=active%3Dtrue%5Erequest_item.number%3DRITM8957975&sysparm_fields=sys_id,number HTTP/1.1" 200 102
DEBUG 2022-07-12 18:17:25,469 - https://api.pwc.com:443 "PATCH /pwcnetwork/service_now/api/now/table/sc_task/a937045b1b28d958437c4152b24bcb28 HTTP/1.1" 200 1066
INFO 2022-07-12 18:17:25,489 - User checked and saved...
DEBUG 2022-07-12 18:26:37,648 - Using proactor: IocpProactor
DEBUG 2022-07-12 18:26:37,796 - Using proactor: IocpProactor
INFO 2022-07-12 18:33:45,181 - Watching for file changes with StatReloader
INFO 2022-07-13 00:09:41,705 - C:\DevOpsTools_Automation\Automation%20Platform\DVT_api\views.py changed, reloading.
DEBUG 2022-07-13 00:09:41,730 - Using proactor: IocpProactor
INFO 2022-07-13 00:09:44,829 - Watching for file changes with StatReloader
INFO 2022-07-13 00:14:17,051 - Watching for file changes with StatReloader
INFO 2022-07-13 11:55:31,147 - Watching for file changes with StatReloader
WARNING 2022-07-13 11:56:01,485 - Bad Request: /api/post_user
INFO 2022-07-13 11:59:06,835 - C:\DevOpsTools_Automation\Automation%20Platform\DVT_api\models.py changed, reloading.
DEBUG 2022-07-13 11:59:06,848 - Using proactor: IocpProactor
INFO 2022-07-13 11:59:08,076 - Watching for file changes with StatReloader
INFO 2022-07-13 11:59:21,081 - Validating GUID: candon001
DEBUG 2022-07-13 11:59:21,087 - Starting new HTTPS connection (1): gumapiservice.pwcinternal.com:443
DEBUG 2022-07-13 11:59:23,322 - https://gumapiservice.pwcinternal.com:443 "POST /GumService.asmx?wsdl HTTP/1.1" 200 1035
INFO 2022-07-13 11:59:23,338 - Creating new ServiceNow ticket......
DEBUG 2022-07-13 11:59:23,339 - Starting new HTTPS connection (1): gumapiservice.pwcinternal.com:443
DEBUG 2022-07-13 11:59:27,636 - https://gumapiservice.pwcinternal.com:443 "POST /GumService.asmx?wsdl HTTP/1.1" 200 404
DEBUG 2022-07-13 11:59:27,640 - Starting new HTTPS connection (1): api.pwc.com:443
DEBUG 2022-07-13 11:59:31,595 - https://api.pwc.com:443 "GET /pwcnetwork/service_now/api/now/table/sc_task?sysparm_query=active%3Dtrue%5Erequest_item.number%3D&sysparm_fields=sys_id,number HTTP/1.1" 200 885
DEBUG 2022-07-13 11:59:31,614 - Starting new HTTPS connection (1): api.pwc.com:443
DEBUG 2022-07-13 11:59:34,472 - https://api.pwc.com:443 "PATCH /pwcnetwork/service_now/api/now/table/sc_task/bfefd4a7db6e97401c46cd4d0b9619cf HTTP/1.1" 200 1393
INFO 2022-07-13 11:59:34,486 - User Catalin Andon saved to data base...
INFO 2022-07-13 12:09:25,311 - C:\DevOpsTools_Automation\Automation%20Platform\DVT_api\views.py changed, reloading.
DEBUG 2022-07-13 12:09:25,312 - Using proactor: IocpProactor
INFO 2022-07-13 12:09:27,306 - Watching for file changes with StatReloader
INFO 2022-07-13 12:09:44,565 - Validating GUID: candon001
DEBUG 2022-07-13 12:09:44,570 - Starting new HTTPS connection (1): gumapiservice.pwcinternal.com:443
DEBUG 2022-07-13 12:09:46,727 - https://gumapiservice.pwcinternal.com:443 "POST /GumService.asmx?wsdl HTTP/1.1" 200 1035
DEBUG 2022-07-13 12:09:46,742 - Starting new HTTPS connection (1): api.pwc.com:443
DEBUG 2022-07-13 12:09:51,171 - https://api.pwc.com:443 "GET /pwcnetwork/service_now/api/now/table/sc_task?sysparm_query=active%3Dtrue%5Erequest_item.number%3D&sysparm_fields=sys_id,number HTTP/1.1" 200 858
DEBUG 2022-07-13 12:09:51,180 - Starting new HTTPS connection (1): api.pwc.com:443
DEBUG 2022-07-13 12:09:53,050 - https://api.pwc.com:443 "PATCH /pwcnetwork/service_now/api/now/table/sc_task/381c1c0c1b3b3494e95f9863b24bcb2d HTTP/1.1" 200 1187
INFO 2022-07-13 12:09:53,051 - RITM number: ---------- was closed!
INFO 2022-07-13 12:09:53,056 - User Catalin Andon saved to data base...
INFO 2022-07-13 12:16:53,219 - C:\DevOpsTools_Automation\Automation%20Platform\DVT_api\views.py changed, reloading.
DEBUG 2022-07-13 12:16:53,220 - Using proactor: IocpProactor
INFO 2022-07-13 12:16:54,529 - Watching for file changes with StatReloader
INFO 2022-07-13 12:17:48,998 - Validating GUID: candon001
DEBUG 2022-07-13 12:17:49,002 - Starting new HTTPS connection (1): gumapiservice.pwcinternal.com:443
DEBUG 2022-07-13 12:17:51,169 - https://gumapiservice.pwcinternal.com:443 "POST /GumService.asmx?wsdl HTTP/1.1" 200 1035
DEBUG 2022-07-13 12:17:51,175 - Starting new HTTPS connection (1): api.pwc.com:443
DEBUG 2022-07-13 12:17:54,915 - https://api.pwc.com:443 "GET /pwcnetwork/service_now/api/now/table/sc_task?sysparm_query=active%3Dtrue%5Erequest_item.number%3D&sysparm_fields=sys_id,number HTTP/1.1" 200 831
DEBUG 2022-07-13 12:17:54,920 - Starting new HTTPS connection (1): api.pwc.com:443
DEBUG 2022-07-13 12:17:56,607 - https://api.pwc.com:443 "PATCH /pwcnetwork/service_now/api/now/table/sc_task/8d35957a1ba08554867564e4604bcbfb HTTP/1.1" 200 1207
INFO 2022-07-13 12:17:56,609 - RITM number: ---------- was closed!
INFO 2022-07-13 12:17:56,624 - User Catalin Andon saved to data base...
INFO 2022-07-13 12:19:48,698 - C:\DevOpsTools_Automation\Automation%20Platform\DVT_api\views.py changed, reloading.
DEBUG 2022-07-13 12:19:48,699 - Using proactor: IocpProactor
INFO 2022-07-13 12:19:50,048 - Watching for file changes with StatReloader
INFO 2022-07-13 12:19:55,650 - Validating GUID: candon001
DEBUG 2022-07-13 12:19:55,654 - Starting new HTTPS connection (1): gumapiservice.pwcinternal.com:443
DEBUG 2022-07-13 12:19:57,772 - https://gumapiservice.pwcinternal.com:443 "POST /GumService.asmx?wsdl HTTP/1.1" 200 1035
INFO 2022-07-13 12:19:57,780 - Creating new ServiceNow ticket......
INFO 2022-07-13 12:19:57,781 - Creating new RITM.....
DEBUG 2022-07-13 12:19:57,783 - Starting new HTTPS connection (1): api.pwc.com:443
DEBUG 2022-07-13 12:20:02,107 - https://api.pwc.com:443 "POST /pwcnetwork/service_now/api/ipwc/request_item/create/d954573ddbe53340a416f5261d9619c0/ritm_nv HTTP/1.1" 201 138
INFO 2022-07-13 12:20:02,109 - RITM RITM8965627 was created...
INFO 2022-07-13 12:20:02,109 - RITM number: -----RITM8965627-----
DEBUG 2022-07-13 12:20:02,111 - Starting new HTTPS connection (1): api.pwc.com:443
DEBUG 2022-07-13 12:20:02,652 - https://api.pwc.com:443 "GET /pwcnetwork/service_now/api/now/table/sc_task?sysparm_query=active%3Dtrue%5Erequest_item.number%3DRITM8965627&sysparm_fields=sys_id,number HTTP/1.1" 200 103
DEBUG 2022-07-13 12:20:02,659 - Starting new HTTPS connection (1): api.pwc.com:443
DEBUG 2022-07-13 12:20:04,401 - https://api.pwc.com:443 "PATCH /pwcnetwork/service_now/api/now/table/sc_task/e00f77971b241d989bfe859ee54bcb14 HTTP/1.1" 200 1062
INFO 2022-07-13 12:20:04,419 - User Catalin Andon saved to data base...
INFO 2022-07-13 12:21:45,464 - C:\DevOpsTools_Automation\Automation%20Platform\DVT_api\SNow_API.py changed, reloading.
DEBUG 2022-07-13 12:21:45,466 - Using proactor: IocpProactor
INFO 2022-07-13 12:21:46,738 - Watching for file changes with StatReloader
INFO 2022-07-13 12:23:35,558 - C:\DevOpsTools_Automation\Automation%20Platform\DVT_api\views.py changed, reloading.
DEBUG 2022-07-13 12:23:35,560 - Using proactor: IocpProactor
INFO 2022-07-13 12:23:37,134 - Watching for file changes with StatReloader
INFO 2022-07-13 16:29:11,553 - C:\DevOpsTools_Automation\Automation%20Platform\DVT_api\views.py changed, reloading.
DEBUG 2022-07-13 16:29:11,565 - Using proactor: IocpProactor
INFO 2022-07-13 16:29:13,637 - Watching for file changes with StatReloader
INFO 2022-07-13 16:36:05,454 - C:\DevOpsTools_Automation\Automation%20Platform\DVT_api\views.py changed, reloading.
DEBUG 2022-07-13 16:36:05,455 - Using proactor: IocpProactor
INFO 2022-07-13 16:36:07,515 - Watching for file changes with StatReloader
INFO 2022-07-13 16:36:11,402 - Validating GUID: candon001
DEBUG 2022-07-13 16:36:11,409 - Starting new HTTPS connection (1): gumapiservice.pwcinternal.com:443
DEBUG 2022-07-13 16:36:13,742 - https://gumapiservice.pwcinternal.com:443 "POST /GumService.asmx?wsdl HTTP/1.1" 200 1035
INFO 2022-07-13 16:36:13,751 - Creating new ServiceNow ticket......
INFO 2022-07-13 16:36:13,751 - Creating new RITM.....
DEBUG 2022-07-13 16:36:13,752 - Starting new HTTPS connection (1): api.pwc.com:443
DEBUG 2022-07-13 16:36:18,319 - https://api.pwc.com:443 "POST /pwcnetwork/service_now/api/ipwc/request_item/create/d954573ddbe53340a416f5261d9619c0/ritm_nv HTTP/1.1" 201 138
INFO 2022-07-13 16:36:18,323 - RITM number: -----RITM8969233-----
DEBUG 2022-07-13 16:36:18,324 - Starting new HTTPS connection (1): api.pwc.com:443
DEBUG 2022-07-13 16:36:18,860 - https://api.pwc.com:443 "GET /pwcnetwork/service_now/api/now/table/sc_task?sysparm_query=active%3Dtrue%5Erequest_item.number%3DRITM8969233&sysparm_fields=sys_id,number HTTP/1.1" 200 103
DEBUG 2022-07-13 16:36:18,864 - Starting new HTTPS connection (1): api.pwc.com:443
DEBUG 2022-07-13 16:36:21,000 - https://api.pwc.com:443 "PATCH /pwcnetwork/service_now/api/now/table/sc_task/2ea978e31b6051d8f96c6282b24bcb3b HTTP/1.1" 200 1064
INFO 2022-07-13 16:36:21,011 - User Catalin Andon saved to data base and added to GUM group
INFO 2022-07-13 16:38:45,200 - C:\DevOpsTools_Automation\Automation%20Platform\DVT_api\views.py changed, reloading.
DEBUG 2022-07-13 16:38:45,200 - Using proactor: IocpProactor
INFO 2022-07-13 16:38:46,368 - Watching for file changes with StatReloader
INFO 2022-07-13 16:38:58,816 - Validating GUID: candon001
DEBUG 2022-07-13 16:38:58,820 - Starting new HTTPS connection (1): gumapiservice.pwcinternal.com:443
DEBUG 2022-07-13 16:39:01,076 - https://gumapiservice.pwcinternal.com:443 "POST /GumService.asmx?wsdl HTTP/1.1" 200 1035
INFO 2022-07-13 16:39:01,079 - Creating new ServiceNow ticket......
INFO 2022-07-13 16:39:01,079 - Creating new RITM.....
DEBUG 2022-07-13 16:39:01,081 - Starting new HTTPS connection (1): api.pwc.com:443
DEBUG 2022-07-13 16:39:04,569 - https://api.pwc.com:443 "POST /pwcnetwork/service_now/api/ipwc/request_item/create/d954573ddbe53340a416f5261d9619c0/ritm_nv HTTP/1.1" 201 138
INFO 2022-07-13 16:39:04,572 - RITM number: -----RITM8969273-----
DEBUG 2022-07-13 16:39:04,574 - Starting new HTTPS connection (1): api.pwc.com:443
DEBUG 2022-07-13 16:39:05,121 - https://api.pwc.com:443 "GET /pwcnetwork/service_now/api/now/table/sc_task?sysparm_query=active%3Dtrue%5Erequest_item.number%3DRITM8969273&sysparm_fields=sys_id,number HTTP/1.1" 200 103
DEBUG 2022-07-13 16:39:05,125 - Starting new HTTPS connection (1): api.pwc.com:443
DEBUG 2022-07-13 16:39:06,936 - https://api.pwc.com:443 "PATCH /pwcnetwork/service_now/api/now/table/sc_task/074a34271b209d98437c4152b24bcb82 HTTP/1.1" 200 1064
INFO 2022-07-13 16:39:06,955 - User Catalin Andon saved to data base and added to GUM group
INFO 2022-07-13 16:42:14,511 - C:\DevOpsTools_Automation\Automation%20Platform\DVT_api\views.py changed, reloading.
DEBUG 2022-07-13 16:42:14,513 - Using proactor: IocpProactor
INFO 2022-07-13 16:42:15,933 - Watching for file changes with StatReloader
INFO 2022-07-13 16:42:22,918 - Validating GUID: candon001
DEBUG 2022-07-13 16:42:22,922 - Starting new HTTPS connection (1): gumapiservice.pwcinternal.com:443
DEBUG 2022-07-13 16:42:25,368 - https://gumapiservice.pwcinternal.com:443 "POST /GumService.asmx?wsdl HTTP/1.1" 200 1035
INFO 2022-07-13 16:42:25,372 - Creating new ServiceNow ticket......
INFO 2022-07-13 16:42:25,373 - Creating new RITM.....
DEBUG 2022-07-13 16:42:25,374 - Starting new HTTPS connection (1): api.pwc.com:443
DEBUG 2022-07-13 16:42:28,891 - https://api.pwc.com:443 "POST /pwcnetwork/service_now/api/ipwc/request_item/create/d954573ddbe53340a416f5261d9619c0/ritm_nv HTTP/1.1" 201 138
INFO 2022-07-13 16:42:28,895 - RITM number: -----RITM8969318-----
DEBUG 2022-07-13 16:42:28,896 - Starting new HTTPS connection (1): api.pwc.com:443
DEBUG 2022-07-13 16:42:29,589 - https://api.pwc.com:443 "GET /pwcnetwork/service_now/api/now/table/sc_task?sysparm_query=active%3Dtrue%5Erequest_item.number%3DRITM8969318&sysparm_fields=sys_id,number HTTP/1.1" 200 103
DEBUG 2022-07-13 16:42:29,596 - Starting new HTTPS connection (1): api.pwc.com:443
DEBUG 2022-07-13 16:42:31,252 - https://api.pwc.com:443 "PATCH /pwcnetwork/service_now/api/now/table/sc_task/bc1b74ab1b6499d8e05a4152b24bcbaa HTTP/1.1" 200 1069
INFO 2022-07-13 16:42:31,264 - User Catalin Andon saved to data base and added to GUM group
INFO 2022-07-13 16:48:18,981 - Validating GUID: tzhang289
DEBUG 2022-07-13 16:48:18,982 - Starting new HTTPS connection (1): gumapiservice.pwcinternal.com:443
DEBUG 2022-07-13 16:48:21,030 - https://gumapiservice.pwcinternal.com:443 "POST /GumService.asmx?wsdl HTTP/1.1" 200 1028
DEBUG 2022-07-13 16:48:21,042 - Starting new HTTPS connection (1): gumapiservice.pwcinternal.com:443
DEBUG 2022-07-13 16:50:04,846 - https://gumapiservice.pwcinternal.com:443 "POST /GumService.asmx?wsdl HTTP/1.1" 200 475
DEBUG 2022-07-13 16:50:04,849 - Starting new HTTPS connection (1): api.pwc.com:443
DEBUG 2022-07-13 16:50:05,570 - https://api.pwc.com:443 "GET /pwcnetwork/service_now/api/now/table/sc_task?sysparm_query=active%3Dtrue%5Erequest_item.number%3DRITM8961419&sysparm_fields=sys_id,number HTTP/1.1" 200 101
DEBUG 2022-07-13 16:50:05,574 - Starting new HTTPS connection (1): api.pwc.com:443
DEBUG 2022-07-13 16:50:07,660 - https://api.pwc.com:443 "PATCH /pwcnetwork/service_now/api/now/table/sc_task/bb0c42171b20d9d8b4636282b24bcb44 HTTP/1.1" 200 1187
INFO 2022-07-13 16:50:07,662 - RITM number: -----RITM8961419----- was closed!
INFO 2022-07-13 16:50:07,684 - User Tony Zhang saved to data base and added to GUM group
INFO 2022-07-13 17:37:57,143 - Validating GUID: candon001
DEBUG 2022-07-13 17:37:57,145 - Starting new HTTPS connection (1): gumapiservice.pwcinternal.com:443
DEBUG 2022-07-13 17:37:59,340 - https://gumapiservice.pwcinternal.com:443 "POST /GumService.asmx?wsdl HTTP/1.1" 200 1035
INFO 2022-07-13 17:37:59,348 - Creating new ServiceNow ticket......
INFO 2022-07-13 17:37:59,348 - Creating new RITM.....
DEBUG 2022-07-13 17:37:59,350 - Starting new HTTPS connection (1): api.pwc.com:443
DEBUG 2022-07-13 17:38:03,077 - https://api.pwc.com:443 "POST /pwcnetwork/service_now/api/ipwc/request_item/create/d954573ddbe53340a416f5261d9619c0/ritm_nv HTTP/1.1" 201 136
INFO 2022-07-13 17:38:03,080 - RITM number: -----RITM8970221-----
DEBUG 2022-07-13 17:38:03,082 - Starting new HTTPS connection (1): api.pwc.com:443
DEBUG 2022-07-13 17:38:03,636 - https://api.pwc.com:443 "GET /pwcnetwork/service_now/api/now/table/sc_task?sysparm_query=active%3Dtrue%5Erequest_item.number%3DRITM8970221&sysparm_fields=sys_id,number HTTP/1.1" 200 103
DEBUG 2022-07-13 17:38:03,640 - Starting new HTTPS connection (1): api.pwc.com:443
DEBUG 2022-07-13 17:38:05,923 - https://api.pwc.com:443 "PATCH /pwcnetwork/service_now/api/now/table/sc_task/0fc789a71bac9d989bfe859ee54bcb5a HTTP/1.1" 200 1060
INFO 2022-07-13 17:38:05,931 - User Catalin Andon saved to data base and added to GUM group
INFO 2022-07-13 17:40:14,535 - C:\DevOpsTools_Automation\Automation%20Platform\DVT_api\models.py changed, reloading.
DEBUG 2022-07-13 17:40:14,536 - Using proactor: IocpProactor
INFO 2022-07-13 17:40:16,798 - Watching for file changes with StatReloader
INFO 2022-07-13 17:42:43,758 - C:\DevOpsTools_Automation\Automation%20Platform\DVT_api\views.py changed, reloading.
DEBUG 2022-07-13 17:42:43,760 - Using proactor: IocpProactor
INFO 2022-07-13 17:42:45,127 - Watching for file changes with StatReloader
INFO 2022-07-13 17:50:51,627 - C:\DevOpsTools_Automation\Automation%20Platform\DVT_api\models.py changed, reloading.
DEBUG 2022-07-13 17:50:51,629 - Using proactor: IocpProactor
INFO 2022-07-13 17:50:54,000 - Watching for file changes with StatReloader
INFO 2022-07-13 17:51:11,175 - Validating GUID: candon001
DEBUG 2022-07-13 17:51:11,178 - Starting new HTTPS connection (1): gumapiservice.pwcinternal.com:443
DEBUG 2022-07-13 17:51:13,429 - https://gumapiservice.pwcinternal.com:443 "POST /GumService.asmx?wsdl HTTP/1.1" 200 1035
DEBUG 2022-07-13 17:51:13,448 - Starting new HTTPS connection (1): gumapiservice.pwcinternal.com:443
DEBUG 2022-07-13 17:51:17,571 - https://gumapiservice.pwcinternal.com:443 "POST /GumService.asmx?wsdl HTTP/1.1" 200 404
DEBUG 2022-07-13 17:51:17,576 - Starting new HTTPS connection (1): api.pwc.com:443
DEBUG 2022-07-13 17:51:18,337 - https://api.pwc.com:443 "GET /pwcnetwork/service_now/api/now/table/sc_task?sysparm_query=active%3Dtrue%5Erequest_item.number%3DTEST0000011111&sysparm_fields=sys_id,number HTTP/1.1" 200 33
ERROR 2022-07-13 17:51:18,539 - Internal Server Error: /api/post_user
Traceback (most recent call last):
  File "C:\Users\candon001\AppData\Local\Programs\Python\Python39\lib\site-packages\django\core\handlers\exception.py", line 47, in inner
    response = get_response(request)
  File "C:\Users\candon001\AppData\Local\Programs\Python\Python39\lib\site-packages\django\core\handlers\base.py", line 181, in _get_response
    response = wrapped_callback(request, *callback_args, **callback_kwargs)
  File "C:\Users\candon001\AppData\Local\Programs\Python\Python39\lib\site-packages\django\views\decorators\csrf.py", line 54, in wrapped_view
    return view_func(*args, **kwargs)
  File "C:\Users\candon001\AppData\Local\Programs\Python\Python39\lib\site-packages\django\views\decorators\csrf.py", line 54, in wrapped_view
    return view_func(*args, **kwargs)
  File "C:\Users\candon001\AppData\Local\Programs\Python\Python39\lib\site-packages\django\views\generic\base.py", line 70, in view
    return self.dispatch(request, *args, **kwargs)
  File "C:\Users\candon001\AppData\Local\Programs\Python\Python39\lib\site-packages\rest_framework\views.py", line 509, in dispatch
    response = self.handle_exception(exc)
  File "C:\Users\candon001\AppData\Local\Programs\Python\Python39\lib\site-packages\rest_framework\views.py", line 469, in handle_exception
    self.raise_uncaught_exception(exc)
  File "C:\Users\candon001\AppData\Local\Programs\Python\Python39\lib\site-packages\rest_framework\views.py", line 480, in raise_uncaught_exception
    raise exc
  File "C:\Users\candon001\AppData\Local\Programs\Python\Python39\lib\site-packages\rest_framework\views.py", line 506, in dispatch
    response = handler(request, *args, **kwargs)
  File "C:\Users\candon001\AppData\Local\Programs\Python\Python39\lib\site-packages\rest_framework\decorators.py", line 50, in handler
    return func(*args, **kwargs)
  File "C:\DevOpsTools_Automation\Automation%20Platform\DVT_api\views.py", line 97, in post_user
    get_active_task.get_active_task_from_current_ritm(ticket)
  File "C:\DevOpsTools_Automation\Automation%20Platform\DVT_api\SNow_API.py", line 74, in get_active_task_from_current_ritm
    task_sys_id = content['result'][0]['sys_id']
IndexError: list index out of range
WARNING 2022-07-13 17:51:45,943 - Bad Request: /api/post_user
INFO 2022-07-13 17:53:43,970 - C:\DevOpsTools_Automation\Automation%20Platform\DVT_api\models.py changed, reloading.
DEBUG 2022-07-13 17:53:43,971 - Using proactor: IocpProactor
INFO 2022-07-13 17:53:45,326 - Watching for file changes with StatReloader
INFO 2022-07-13 17:54:08,458 - Validating GUID: candon001
DEBUG 2022-07-13 17:54:08,462 - Starting new HTTPS connection (1): gumapiservice.pwcinternal.com:443
DEBUG 2022-07-13 17:54:10,557 - https://gumapiservice.pwcinternal.com:443 "POST /GumService.asmx?wsdl HTTP/1.1" 200 1035
INFO 2022-07-13 17:54:10,561 - Creating new ServiceNow ticket......
INFO 2022-07-13 17:54:10,561 - Creating new RITM.....
DEBUG 2022-07-13 17:54:10,562 - Starting new HTTPS connection (1): api.pwc.com:443
DEBUG 2022-07-13 17:54:16,669 - https://api.pwc.com:443 "POST /pwcnetwork/service_now/api/ipwc/request_item/create/d954573ddbe53340a416f5261d9619c0/ritm_nv HTTP/1.1" 201 138
INFO 2022-07-13 17:54:16,671 - RITM number: -----RITM8970498-----
DEBUG 2022-07-13 17:54:16,672 - Starting new HTTPS connection (1): api.pwc.com:443
DEBUG 2022-07-13 17:54:17,253 - https://api.pwc.com:443 "GET /pwcnetwork/service_now/api/now/table/sc_task?sysparm_query=active%3Dtrue%5Erequest_item.number%3DRITM8970498&sysparm_fields=sys_id,number HTTP/1.1" 200 103
DEBUG 2022-07-13 17:54:17,258 - Starting new HTTPS connection (1): api.pwc.com:443
DEBUG 2022-07-13 17:54:18,852 - https://api.pwc.com:443 "PATCH /pwcnetwork/service_now/api/now/table/sc_task/e88b49e71b2819d801f9dd72b24bcbf1 HTTP/1.1" 200 1066
INFO 2022-07-13 17:54:18,875 - User Catalin Andon saved to data base and added to GUM group
DEBUG 2022-07-13 17:57:34,251 - Using proactor: IocpProactor
DEBUG 2022-07-13 17:57:34,351 - Using proactor: IocpProactor
INFO 2022-07-13 17:58:05,873 - Watching for file changes with StatReloader
INFO 2022-07-13 18:09:49,260 - Validating GUID: candon001
DEBUG 2022-07-13 18:09:49,267 - Starting new HTTPS connection (1): gumapiservice.pwcinternal.com:443
DEBUG 2022-07-13 18:09:51,504 - https://gumapiservice.pwcinternal.com:443 "POST /GumService.asmx?wsdl HTTP/1.1" 200 1035
INFO 2022-07-13 18:09:51,515 - Creating new ServiceNow ticket......
INFO 2022-07-13 18:09:51,515 - Creating new RITM.....
DEBUG 2022-07-13 18:09:51,517 - Starting new HTTPS connection (1): api.pwc.com:443
DEBUG 2022-07-13 18:09:55,360 - https://api.pwc.com:443 "POST /pwcnetwork/service_now/api/ipwc/request_item/create/d954573ddbe53340a416f5261d9619c0/ritm_nv HTTP/1.1" 201 137
INFO 2022-07-13 18:09:55,364 - RITM number: -----RITM8970707-----
DEBUG 2022-07-13 18:09:55,365 - Starting new HTTPS connection (1): api.pwc.com:443
DEBUG 2022-07-13 18:09:56,221 - https://api.pwc.com:443 "GET /pwcnetwork/service_now/api/now/table/sc_task?sysparm_query=active%3Dtrue%5Erequest_item.number%3DRITM8970707&sysparm_fields=sys_id,number HTTP/1.1" 200 103
DEBUG 2022-07-13 18:09:56,226 - Starting new HTTPS connection (1): api.pwc.com:443
DEBUG 2022-07-13 18:09:57,839 - https://api.pwc.com:443 "PATCH /pwcnetwork/service_now/api/now/table/sc_task/f51fc96f1ba819d801f9dd72b24bcb84 HTTP/1.1" 200 1065
INFO 2022-07-13 18:09:57,857 - User Catalin Andon saved to data base and added to GUM group
INFO 2022-07-13 18:13:41,688 - Validating GUID: ashenoy017
DEBUG 2022-07-13 18:13:41,690 - Starting new HTTPS connection (1): gumapiservice.pwcinternal.com:443
DEBUG 2022-07-13 18:13:43,974 - https://gumapiservice.pwcinternal.com:443 "POST /GumService.asmx?wsdl HTTP/1.1" 200 1028
DEBUG 2022-07-13 18:13:43,985 - Starting new HTTPS connection (1): gumapiservice.pwcinternal.com:443
DEBUG 2022-07-13 18:15:27,650 - https://gumapiservice.pwcinternal.com:443 "POST /GumService.asmx?wsdl HTTP/1.1" 200 475
DEBUG 2022-07-13 18:15:27,653 - Starting new HTTPS connection (1): api.pwc.com:443
DEBUG 2022-07-13 18:15:28,700 - https://api.pwc.com:443 "GET /pwcnetwork/service_now/api/now/table/sc_task?sysparm_query=active%3Dtrue%5Erequest_item.number%3DRITM8961836&sysparm_fields=sys_id,number HTTP/1.1" 200 103
DEBUG 2022-07-13 18:15:28,703 - Starting new HTTPS connection (1): api.pwc.com:443
DEBUG 2022-07-13 18:15:30,242 - https://api.pwc.com:443 "PATCH /pwcnetwork/service_now/api/now/table/sc_task/415216d71b64d9d8b4636282b24bcb33 HTTP/1.1" 200 1188
INFO 2022-07-13 18:15:30,244 - RITM number: -----RITM8961836----- was closed!
INFO 2022-07-13 18:15:30,249 - User Adi Shenoy saved to data base and added to GUM group
INFO 2022-07-13 18:34:36,589 - Validating GUID: candon001
DEBUG 2022-07-13 18:34:36,591 - Starting new HTTPS connection (1): gumapiservice.pwcinternal.com:443
DEBUG 2022-07-13 18:34:38,952 - https://gumapiservice.pwcinternal.com:443 "POST /GumService.asmx?wsdl HTTP/1.1" 200 1035
INFO 2022-07-13 18:34:38,968 - Creating new ServiceNow ticket......
INFO 2022-07-13 18:34:38,968 - Creating new RITM.....
DEBUG 2022-07-13 18:34:38,970 - Starting new HTTPS connection (1): api.pwc.com:443
DEBUG 2022-07-13 18:34:42,444 - https://api.pwc.com:443 "POST /pwcnetwork/service_now/api/ipwc/request_item/create/d954573ddbe53340a416f5261d9619c0/ritm_nv HTTP/1.1" 201 137
INFO 2022-07-13 18:34:42,447 - RITM number: -----RITM8971049-----
DEBUG 2022-07-13 18:34:42,450 - Starting new HTTPS connection (1): api.pwc.com:443
DEBUG 2022-07-13 18:34:43,355 - https://api.pwc.com:443 "GET /pwcnetwork/service_now/api/now/table/sc_task?sysparm_query=active%3Dtrue%5Erequest_item.number%3DRITM8971049&sysparm_fields=sys_id,number HTTP/1.1" 200 103
DEBUG 2022-07-13 18:34:43,359 - Starting new HTTPS connection (1): api.pwc.com:443
DEBUG 2022-07-13 18:34:45,282 - https://api.pwc.com:443 "PATCH /pwcnetwork/service_now/api/now/table/sc_task/7cc495271bec9d98437c4152b24bcb81 HTTP/1.1" 200 1066
INFO 2022-07-13 18:34:45,298 - User Catalin Andon saved to data base and added to GUM group
INFO 2022-07-13 18:40:06,885 - Validating GUID: ytang114
DEBUG 2022-07-13 18:40:06,887 - Starting new HTTPS connection (1): gumapiservice.pwcinternal.com:443
DEBUG 2022-07-13 18:40:09,030 - https://gumapiservice.pwcinternal.com:443 "POST /GumService.asmx?wsdl HTTP/1.1" 200 1031
DEBUG 2022-07-13 18:40:09,054 - Starting new HTTPS connection (1): gumapiservice.pwcinternal.com:443
DEBUG 2022-07-13 18:41:53,821 - https://gumapiservice.pwcinternal.com:443 "POST /GumService.asmx?wsdl HTTP/1.1" 200 475
DEBUG 2022-07-13 18:41:53,824 - Starting new HTTPS connection (1): api.pwc.com:443
DEBUG 2022-07-13 18:41:54,846 - https://api.pwc.com:443 "GET /pwcnetwork/service_now/api/now/table/sc_task?sysparm_query=active%3Dtrue%5Erequest_item.number%3DRITM8962498&sysparm_fields=sys_id,number HTTP/1.1" 200 103
DEBUG 2022-07-13 18:41:54,852 - Starting new HTTPS connection (1): api.pwc.com:443
DEBUG 2022-07-13 18:41:56,668 - https://api.pwc.com:443 "PATCH /pwcnetwork/service_now/api/now/table/sc_task/9d8f3a931bec5dd8b4636282b24bcb61 HTTP/1.1" 200 1192
INFO 2022-07-13 18:41:56,722 - RITM number: -----RITM8962498----- was closed!
INFO 2022-07-13 18:41:57,615 - User Yixuan Tang saved to data base and added to GUM group
INFO 2022-07-14 00:22:35,992 - Validating GUID: ytang11
DEBUG 2022-07-14 00:22:35,997 - Starting new HTTPS connection (1): gumapiservice.pwcinternal.com:443
DEBUG 2022-07-14 00:22:38,621 - https://gumapiservice.pwcinternal.com:443 "POST /GumService.asmx?wsdl HTTP/1.1" 200 486
ERROR 2022-07-14 00:22:38,862 - Internal Server Error: /api/post_user
Traceback (most recent call last):
  File "C:\Users\candon001\AppData\Local\Programs\Python\Python39\lib\site-packages\django\core\handlers\exception.py", line 47, in inner
    response = get_response(request)
  File "C:\Users\candon001\AppData\Local\Programs\Python\Python39\lib\site-packages\django\core\handlers\base.py", line 181, in _get_response
    response = wrapped_callback(request, *callback_args, **callback_kwargs)
  File "C:\Users\candon001\AppData\Local\Programs\Python\Python39\lib\site-packages\django\views\decorators\csrf.py", line 54, in wrapped_view
    return view_func(*args, **kwargs)
  File "C:\Users\candon001\AppData\Local\Programs\Python\Python39\lib\site-packages\django\views\decorators\csrf.py", line 54, in wrapped_view
    return view_func(*args, **kwargs)
  File "C:\Users\candon001\AppData\Local\Programs\Python\Python39\lib\site-packages\django\views\generic\base.py", line 70, in view
    return self.dispatch(request, *args, **kwargs)
  File "C:\Users\candon001\AppData\Local\Programs\Python\Python39\lib\site-packages\rest_framework\views.py", line 509, in dispatch
    response = self.handle_exception(exc)
  File "C:\Users\candon001\AppData\Local\Programs\Python\Python39\lib\site-packages\rest_framework\views.py", line 469, in handle_exception
    self.raise_uncaught_exception(exc)
  File "C:\Users\candon001\AppData\Local\Programs\Python\Python39\lib\site-packages\rest_framework\views.py", line 480, in raise_uncaught_exception
    raise exc
  File "C:\Users\candon001\AppData\Local\Programs\Python\Python39\lib\site-packages\rest_framework\views.py", line 506, in dispatch
    response = handler(request, *args, **kwargs)
  File "C:\Users\candon001\AppData\Local\Programs\Python\Python39\lib\site-packages\rest_framework\decorators.py", line 50, in handler
    return func(*args, **kwargs)
  File "C:\DevOpsTools_Automation\Automation%20Platform\DVT_api\views.py", line 74, in post_user
    email_address = children1[1][3].text
  File "src\lxml\etree.pyx", line 1161, in lxml.etree._Element.__getitem__
IndexError: list index out of range
INFO 2022-07-14 00:31:07,382 - C:\DevOpsTools_Automation\Automation%20Platform\DVT_api\views.py changed, reloading.
DEBUG 2022-07-14 00:31:07,391 - Using proactor: IocpProactor
INFO 2022-07-14 00:31:11,517 - Watching for file changes with StatReloader
INFO 2022-07-14 00:31:21,652 - Validating GUID: ytang11
DEBUG 2022-07-14 00:31:21,660 - Starting new HTTPS connection (1): gumapiservice.pwcinternal.com:443
DEBUG 2022-07-14 00:31:24,259 - https://gumapiservice.pwcinternal.com:443 "POST /GumService.asmx?wsdl HTTP/1.1" 200 486
ERROR 2022-07-14 00:31:24,357 - Internal Server Error: /api/post_user
Traceback (most recent call last):
  File "C:\Users\candon001\AppData\Local\Programs\Python\Python39\lib\site-packages\django\core\handlers\exception.py", line 47, in inner
    response = get_response(request)
  File "C:\Users\candon001\AppData\Local\Programs\Python\Python39\lib\site-packages\django\core\handlers\base.py", line 181, in _get_response
    response = wrapped_callback(request, *callback_args, **callback_kwargs)
  File "C:\Users\candon001\AppData\Local\Programs\Python\Python39\lib\site-packages\django\views\decorators\csrf.py", line 54, in wrapped_view
    return view_func(*args, **kwargs)
  File "C:\Users\candon001\AppData\Local\Programs\Python\Python39\lib\site-packages\django\views\decorators\csrf.py", line 54, in wrapped_view
    return view_func(*args, **kwargs)
  File "C:\Users\candon001\AppData\Local\Programs\Python\Python39\lib\site-packages\django\views\generic\base.py", line 70, in view
    return self.dispatch(request, *args, **kwargs)
  File "C:\Users\candon001\AppData\Local\Programs\Python\Python39\lib\site-packages\rest_framework\views.py", line 509, in dispatch
    response = self.handle_exception(exc)
  File "C:\Users\candon001\AppData\Local\Programs\Python\Python39\lib\site-packages\rest_framework\views.py", line 469, in handle_exception
    self.raise_uncaught_exception(exc)
  File "C:\Users\candon001\AppData\Local\Programs\Python\Python39\lib\site-packages\rest_framework\views.py", line 480, in raise_uncaught_exception
    raise exc
  File "C:\Users\candon001\AppData\Local\Programs\Python\Python39\lib\site-packages\rest_framework\views.py", line 506, in dispatch
    response = handler(request, *args, **kwargs)
  File "C:\Users\candon001\AppData\Local\Programs\Python\Python39\lib\site-packages\rest_framework\decorators.py", line 50, in handler
    return func(*args, **kwargs)
  File "C:\DevOpsTools_Automation\Automation%20Platform\DVT_api\views.py", line 74, in post_user
    email_address = children1[1][3].text
  File "src\lxml\etree.pyx", line 1161, in lxml.etree._Element.__getitem__
IndexError: list index out of range
INFO 2022-07-14 00:31:51,309 - Validating GUID: ytang11
DEBUG 2022-07-14 00:31:51,311 - Starting new HTTPS connection (1): gumapiservice.pwcinternal.com:443
DEBUG 2022-07-14 00:31:53,683 - https://gumapiservice.pwcinternal.com:443 "POST /GumService.asmx?wsdl HTTP/1.1" 200 486
ERROR 2022-07-14 00:31:53,761 - Internal Server Error: /api/post_user
Traceback (most recent call last):
  File "C:\Users\candon001\AppData\Local\Programs\Python\Python39\lib\site-packages\django\core\handlers\exception.py", line 47, in inner
    response = get_response(request)
  File "C:\Users\candon001\AppData\Local\Programs\Python\Python39\lib\site-packages\django\core\handlers\base.py", line 181, in _get_response
    response = wrapped_callback(request, *callback_args, **callback_kwargs)
  File "C:\Users\candon001\AppData\Local\Programs\Python\Python39\lib\site-packages\django\views\decorators\csrf.py", line 54, in wrapped_view
    return view_func(*args, **kwargs)
  File "C:\Users\candon001\AppData\Local\Programs\Python\Python39\lib\site-packages\django\views\decorators\csrf.py", line 54, in wrapped_view
    return view_func(*args, **kwargs)
  File "C:\Users\candon001\AppData\Local\Programs\Python\Python39\lib\site-packages\django\views\generic\base.py", line 70, in view
    return self.dispatch(request, *args, **kwargs)
  File "C:\Users\candon001\AppData\Local\Programs\Python\Python39\lib\site-packages\rest_framework\views.py", line 509, in dispatch
    response = self.handle_exception(exc)
  File "C:\Users\candon001\AppData\Local\Programs\Python\Python39\lib\site-packages\rest_framework\views.py", line 469, in handle_exception
    self.raise_uncaught_exception(exc)
  File "C:\Users\candon001\AppData\Local\Programs\Python\Python39\lib\site-packages\rest_framework\views.py", line 480, in raise_uncaught_exception
    raise exc
  File "C:\Users\candon001\AppData\Local\Programs\Python\Python39\lib\site-packages\rest_framework\views.py", line 506, in dispatch
    response = handler(request, *args, **kwargs)
  File "C:\Users\candon001\AppData\Local\Programs\Python\Python39\lib\site-packages\rest_framework\decorators.py", line 50, in handler
    return func(*args, **kwargs)
  File "C:\DevOpsTools_Automation\Automation%20Platform\DVT_api\views.py", line 74, in post_user
    email_address = children1[1][3].text
  File "src\lxml\etree.pyx", line 1161, in lxml.etree._Element.__getitem__
IndexError: list index out of range
INFO 2022-07-14 00:32:39,729 - C:\DevOpsTools_Automation\Automation%20Platform\DVT_api\views.py changed, reloading.
DEBUG 2022-07-14 00:32:39,730 - Using proactor: IocpProactor
INFO 2022-07-14 00:32:43,080 - Watching for file changes with StatReloader
INFO 2022-07-14 00:32:54,230 - Validating GUID: ytang11
DEBUG 2022-07-14 00:32:54,241 - Starting new HTTPS connection (1): gumapiservice.pwcinternal.com:443
DEBUG 2022-07-14 00:32:56,872 - https://gumapiservice.pwcinternal.com:443 "POST /GumService.asmx?wsdl HTTP/1.1" 200 486
ERROR 2022-07-14 00:32:56,944 - Internal Server Error: /api/post_user
Traceback (most recent call last):
  File "C:\Users\candon001\AppData\Local\Programs\Python\Python39\lib\site-packages\django\core\handlers\exception.py", line 47, in inner
    response = get_response(request)
  File "C:\Users\candon001\AppData\Local\Programs\Python\Python39\lib\site-packages\django\core\handlers\base.py", line 181, in _get_response
    response = wrapped_callback(request, *callback_args, **callback_kwargs)
  File "C:\Users\candon001\AppData\Local\Programs\Python\Python39\lib\site-packages\django\views\decorators\csrf.py", line 54, in wrapped_view
    return view_func(*args, **kwargs)
  File "C:\Users\candon001\AppData\Local\Programs\Python\Python39\lib\site-packages\django\views\decorators\csrf.py", line 54, in wrapped_view
    return view_func(*args, **kwargs)
  File "C:\Users\candon001\AppData\Local\Programs\Python\Python39\lib\site-packages\django\views\generic\base.py", line 70, in view
    return self.dispatch(request, *args, **kwargs)
  File "C:\Users\candon001\AppData\Local\Programs\Python\Python39\lib\site-packages\rest_framework\views.py", line 509, in dispatch
    response = self.handle_exception(exc)
  File "C:\Users\candon001\AppData\Local\Programs\Python\Python39\lib\site-packages\rest_framework\views.py", line 469, in handle_exception
    self.raise_uncaught_exception(exc)
  File "C:\Users\candon001\AppData\Local\Programs\Python\Python39\lib\site-packages\rest_framework\views.py", line 480, in raise_uncaught_exception
    raise exc
  File "C:\Users\candon001\AppData\Local\Programs\Python\Python39\lib\site-packages\rest_framework\views.py", line 506, in dispatch
    response = handler(request, *args, **kwargs)
  File "C:\Users\candon001\AppData\Local\Programs\Python\Python39\lib\site-packages\rest_framework\decorators.py", line 50, in handler
    return func(*args, **kwargs)
  File "C:\DevOpsTools_Automation\Automation%20Platform\DVT_api\views.py", line 74, in post_user
    email_address = children1[1][3].text
  File "src\lxml\etree.pyx", line 1161, in lxml.etree._Element.__getitem__
IndexError: list index out of range
INFO 2022-07-14 00:38:13,935 - C:\DevOpsTools_Automation\Automation%20Platform\DVT_api\views.py changed, reloading.
DEBUG 2022-07-14 00:38:13,936 - Using proactor: IocpProactor
INFO 2022-07-14 00:38:17,214 - Watching for file changes with StatReloader
INFO 2022-07-14 00:38:47,932 - C:\DevOpsTools_Automation\Automation%20Platform\DVT_api\views.py changed, reloading.
DEBUG 2022-07-14 00:38:47,933 - Using proactor: IocpProactor
INFO 2022-07-14 00:38:50,054 - Watching for file changes with StatReloader
INFO 2022-07-14 00:38:56,793 - Validating GUID: ytang11
DEBUG 2022-07-14 00:38:56,803 - Starting new HTTPS connection (1): gumapiservice.pwcinternal.com:443
DEBUG 2022-07-14 00:38:59,129 - https://gumapiservice.pwcinternal.com:443 "POST /GumService.asmx?wsdl HTTP/1.1" 200 486
WARNING 2022-07-14 00:38:59,139 - Bad Request: /api/post_user
INFO 2022-07-14 00:41:48,582 - C:\DevOpsTools_Automation\Automation%20Platform\DVT_api\views.py changed, reloading.
DEBUG 2022-07-14 00:41:48,584 - Using proactor: IocpProactor
INFO 2022-07-14 00:41:51,283 - Watching for file changes with StatReloader
INFO 2022-07-14 00:45:36,690 - C:\DevOpsTools_Automation\Automation%20Platform\DVT_api\views.py changed, reloading.
DEBUG 2022-07-14 00:45:36,692 - Using proactor: IocpProactor
INFO 2022-07-14 00:45:39,252 - Watching for file changes with StatReloader
DEBUG 2022-07-14 00:48:51,351 - Using proactor: IocpProactor
DEBUG 2022-07-14 00:48:51,503 - Using proactor: IocpProactor
DEBUG 2022-08-03 22:34:24,746 - Using proactor: IocpProactor
INFO 2022-08-08 16:40:30,915 - Watching for file changes with StatReloader
DEBUG 2022-08-08 16:41:50,689 - Using proactor: IocpProactor
DEBUG 2022-08-08 16:41:50,799 - Using proactor: IocpProactor
INFO 2022-08-08 16:42:25,795 - Watching for file changes with StatReloader
DEBUG 2022-08-08 17:40:43,803 - Using proactor: IocpProactor
DEBUG 2022-08-08 17:40:43,925 - Using proactor: IocpProactor
INFO 2022-08-08 17:40:50,875 - Watching for file changes with StatReloader
WARNING 2022-08-08 17:41:01,267 - Not Found: /
WARNING 2022-08-08 17:41:01,608 - Not Found: /favicon.ico
WARNING 2022-08-08 17:41:12,118 - Not Found: /api
WARNING 2022-08-08 17:41:19,051 - Not Found: /api/
WARNING 2022-08-08 17:44:13,541 - Unauthorized: /api/get_user
WARNING 2022-08-08 17:44:15,340 - Unauthorized: /api/get_user
INFO 2022-08-09 10:37:13,178 - C:\DevOpsTools_Automation\Automation%20Platform\DevOpsTools_Automation\urls.py changed, reloading.
DEBUG 2022-08-09 10:37:13,200 - Using proactor: IocpProactor
INFO 2022-08-09 10:37:16,283 - Watching for file changes with StatReloader
WARNING 2022-08-09 10:40:37,194 - Not Found: /
WARNING 2022-08-09 10:40:37,623 - Not Found: /favicon.ico
INFO 2022-08-09 10:43:58,858 - C:\DevOpsTools_Automation\Automation%20Platform\DevOpsTools_Automation\urls.py changed, reloading.
DEBUG 2022-08-09 10:43:58,860 - Using proactor: IocpProactor
INFO 2022-08-09 10:44:00,608 - Watching for file changes with StatReloader
WARNING 2022-08-09 10:57:06,037 - Not Found: /
WARNING 2022-08-09 11:08:24,024 - Not Found: /
INFO 2022-08-09 11:10:53,042 - C:\DevOpsTools_Automation\Automation%20Platform\DVT_api\urls.py changed, reloading.
DEBUG 2022-08-09 11:10:53,043 - Using proactor: IocpProactor
INFO 2022-08-09 11:10:55,255 - Watching for file changes with StatReloader
WARNING 2022-08-09 11:11:01,586 - Not Found: /
INFO 2022-08-09 11:17:55,345 - C:\DevOpsTools_Automation\Automation%20Platform\DevOpsTools_Automation\urls.py changed, reloading.
DEBUG 2022-08-09 11:17:55,345 - Using proactor: IocpProactor
INFO 2022-08-09 11:17:56,674 - Watching for file changes with StatReloader
DEBUG 2022-08-09 12:22:40,439 - Using proactor: IocpProactor
DEBUG 2022-08-09 12:22:40,556 - Using proactor: IocpProactor
INFO 2022-08-14 14:50:32,298 - Watching for file changes with StatReloader
WARNING 2022-08-14 14:50:45,089 - Not Found: /
WARNING 2022-08-14 14:50:54,995 - Not Found: /home
INFO 2022-08-14 14:52:06,296 - C:\DevOpsTools_Automation\Automation%20Platform\DevOpsTools_Automation\urls.py changed, reloading.
DEBUG 2022-08-14 14:52:06,323 - Using proactor: IocpProactor
INFO 2022-08-14 14:52:08,121 - Watching for file changes with StatReloader
WARNING 2022-08-14 14:52:45,658 - Not Found: /favicon.ico
WARNING 2022-08-14 14:54:03,733 - Not Found: /test-api
DEBUG 2022-08-16 13:50:25,942 - Using proactor: IocpProactor
DEBUG 2022-08-16 13:50:26,200 - Using proactor: IocpProactor
INFO 2022-08-16 19:33:58,705 - Watching for file changes with StatReloader
WARNING 2022-08-16 19:45:27,113 - Not Found: /
INFO 2022-08-16 19:48:55,169 - Validating GUID: ytang114
DEBUG 2022-08-16 19:48:55,176 - Starting new HTTPS connection (1): gumapiservice.pwcinternal.com:443
DEBUG 2022-08-16 19:48:57,525 - https://gumapiservice.pwcinternal.com:443 "POST /GumService.asmx?wsdl HTTP/1.1" 200 1031
INFO 2022-08-16 19:48:57,548 - Creating new ServiceNow ticket......
INFO 2022-08-16 19:48:57,549 - Creating new RITM.....
DEBUG 2022-08-16 19:48:57,551 - Starting new HTTPS connection (1): api.pwc.com:443
DEBUG 2022-08-16 19:49:02,149 - https://api.pwc.com:443 "POST /pwcnetwork/service_now/api/ipwc/request_item/create/d954573ddbe53340a416f5261d9619c0/ritm_nv HTTP/1.1" 201 137
INFO 2022-08-16 19:49:02,162 - RITM number: -----RITM9300196-----
DEBUG 2022-08-16 19:49:02,163 - Starting new HTTPS connection (1): api.pwc.com:443
DEBUG 2022-08-16 19:49:03,666 - https://api.pwc.com:443 "GET /pwcnetwork/service_now/api/now/table/sc_task?sysparm_query=active%3Dtrue%5Erequest_item.number%3DRITM9300196&sysparm_fields=sys_id,number HTTP/1.1" 200 103
DEBUG 2022-08-16 19:49:03,671 - Starting new HTTPS connection (1): api.pwc.com:443
DEBUG 2022-08-16 19:49:05,877 - https://api.pwc.com:443 "PATCH /pwcnetwork/service_now/api/now/table/sc_task/45dbec2a1b5dd15c4d78cb75464bcb63 HTTP/1.1" 200 1060
INFO 2022-08-16 19:49:05,896 - User Yixuan Tang saved to data base and added to GUM group
DEBUG 2022-08-16 20:01:41,998 - Using proactor: IocpProactor
DEBUG 2022-08-16 20:01:42,140 - Using proactor: IocpProactor
INFO 2022-08-16 20:12:24,283 - Watching for file changes with StatReloader
WARNING 2022-08-16 20:13:58,823 - Not Found: /test-ui/schema
WARNING 2022-08-16 20:14:07,180 - Not Found: /test-ui/schema/
INFO 2022-08-17 15:32:44,414 - C:\DevOpsTools_Automation\Automation%20Platform\DVT_api\models.py changed, reloading.
DEBUG 2022-08-17 15:32:44,462 - Using proactor: IocpProactor
INFO 2022-08-17 15:32:49,153 - Watching for file changes with StatReloader
